Workbook
Name _GoBack: 'INGENIERÍA FABRICA'!#REF!
Name _GoBack: 'MASTER INGENIERÍA CLIENTE'!#REF!
Name _GoBack: 'MASTER U3'!#REF!
Name _GoBack: 'SDI o TRL CLIENTE'!#REF!
Name NombreDocumento: 'INGENIERÍA FABRICA'!#REF!
Name NombreDocumento: 'MASTER INGENIERÍA CLIENTE'!#REF!
Name NombreDocumento: 'MASTER U3'!#REF!
Name NombreDocumento: 'SDI o TRL CLIENTE'!#REF!

Sheet MASTER INGENIERÍA CLIENTE
Q1: FECHA: | R1: =TODAY() -> 46130
E2: CANTIDAD DE DOCUMENTOS | H2: =SUBTOTAL(3,H4:H244) -> 222 | N2: RESUMEN | V2: 1ERA EMISIÓN | Z2: COMENTARIOS CLIENTE | AD2: 2DA EMISIÓN | AH2: COMENTARIOS CLIENTE | AL2: 3ERA EMISIÓN | AP2: COMENTARIOS CLIENTE | AT2: 4TA EMISIÓN | AX2: COMENTARIOS CLIENTE | BB2: 5TA EMISIÓN | BF2: COMENTARIOS CLIENTE | BJ2: 6TA EMISIÓN | BN2: COMENTARIOS CLIENTE | BR2: 7MA EMISIÓN | BV2: COMENTARIOS CLIENTE | BZ2: 8VA EMISIÓN | CD2: COMENTARIOS CLIENTE | CH2: 9NA EMISIÓN | CL2: COMENTARIOS CLIENTE | CP2: 10MA EMISIÓN | CT2: COMENTARIOS CLIENTE | CX2: EMISIÓN | DB2: COMENTARIOS CLIENTE | DF2: EMISIÓN | DJ2: COMENTARIOS CLIENTE | DN2: EMISIÓN | DR2: COMENTARIOS CLIENTE | DV2: EMISIÓN | DZ2: COMENTARIOS CLIENTE | ED2: EMISIÓN | EH2: COMENTARIOS CLIENTE | EL2: EMISIÓN | EP2: COMENTARIOS CLIENTE | ET2: EMISIÓN | EX2: COMENTARIOS CLIENTE | FB2: EMISIÓN | FF2: COMENTARIOS CLIENTE | FJ2: EMISIÓN | FN2: COMENTARIOS CLIENTE | FR2: EMISIÓN | FV2: COMENTARIOS CLIENTE | FZ2: EMISIÓN | GD2: COMENTARIOS CLIENTE | GH2: EMISIÓN | GL2: COMENTARIOS CLIENTE | GP2: EMISIÓN | GT2: COMENTARIOS CLIENTE
B3: << | C3: Tipo de ing | D3: SALA / TAG | E3: CÓDIGO SEGURA | F3: CÓDIGO INN | G3: CÓDIGO CODELCO CHUQUICAMATA | H3: DESCRIPCIÓN DE DOCUMENTO | I3: COMPROMISO DE ENTREGA SEGURA (1 semana corrida) | J3: CRITICIDAD | K3: DEADLINE CLIENTE (1 semana corrida) | L3: COMENTARIO INTERNO | M3: DISCIPLINA | N3: REVISIÓN | O3: ACTA DE ENVÍO O TRL | P3: FECHA ÚLTIMO ENVÍO SEH | Q3: FECHA RESPUESTA CLIENTE | R3: ESTATUS | S3: INDICADOR SEH DIAS LEVANTANDO COMENTARIOS) | T3: DÍAS EN REVISIÓN INN | U3: N° EMISIONES REALIZADAS | V3: REVISION | W3: TRANSMITTAL SEH | X3: TIEMPO RESPUESTA | Y3: FECHA EMITIDO | Z3: TRANSMITTAL | AA3: FECHA | AB3: TIEMPO RESPUESTA | AC3: OBS | AD3: REVISION | AE3: TRANSMITTAL SEH | AF3: DIAS EN LEVANTAR COMENTARIOS | AG3: FECHA | AH3: TRANSMITTAL | AI3: FECHA | AJ3: TIEMPO RESPUESTA | AK3: OBS | AL3: REVISION | AM3: TRANSMITTAL SEH | AN3: TIEMPO RESPUESTA | AO3: FECHA | AP3: TRANSMITTAL | AQ3: FECHA | AR3: TIEMPO RESPUESTA | AS3: OBS | AT3: REVISION | AU3: TRANSMITTAL SEH | AV3: TIEMPO RESPUESTA | AW3: FECHA | AX3: TRANSMITTAL | AY3: FECHA | AZ3: TIEMPO RESPUESTA | BA3: OBS | BB3: REVISION | BC3: TRANSMITTAL SEH | BD3: TIEMPO RESPUESTA | BE3: FECHA | BF3: TRANSMITTAL | BG3: FECHA | BH3: TIEMPO RESPUESTA | BI3: OBS | BJ3: REVISION | BK3: TRANSMITTAL SEH | BL3: TIEMPO RESPUESTA | BM3: FECHA | BN3: TRANSMITTAL | BO3: FECHA | BP3: TIEMPO RESPUESTA | BQ3: OBS | BR3: REVISION | BS3: TRANSMITTAL SEH | BT3: TIEMPO RESPUESTA | BU3: FECHA | BV3: TRANSMITTAL | BW3: FECHA | BX3: TIEMPO RESPUESTA | BY3: OBS | BZ3: REVISION | CA3: TRANSMITTAL SEH | CB3: TIEMPO RESPUESTA | CC3: FECHA | CD3: TRANSMITTAL | CE3: FECHA | CF3: TIEMPO RESPUESTA | CG3: OBS | CH3: REVISION | CI3: TRANSMITTAL SEH | CJ3: TIEMPO RESPUESTA | CK3: FECHA | CL3: TRANSMITTAL | CM3: FECHA | CN3: TIEMPO RESPUESTA | CO3: OBS | CP3: REVISION | CQ3: TRANSMITTAL SEH | CR3: TIEMPO RESPUESTA | CS3: FECHA | CT3: TRANSMITTAL SIEMENS | CU3: FECHA | CV3: TIEMPO RESPUESTA | CW3: OBS | CX3: REVISION | CY3: TRANSMITTAL SEH | CZ3: TIEMPO RESPUESTA | DA3: FECHA | DB3: TRANSMITTAL SIEMENS | DC3: FECHA | DD3: TIEMPO RESPUESTA | DE3: OBS | DF3: REVISION | DG3: TRANSMITTAL SEH | DH3: TIEMPO RESPUESTA | DI3: FECHA | DJ3: TRANSMITTAL SIEMENS | DK3: FECHA | DL3: TIEMPO RESPUESTA | DM3: OBS | DN3: REVISION | DO3: TRANSMITTAL SEH | DP3: TIEMPO RESPUESTA | DQ3: FECHA | DR3: TRANSMITTAL SIEMENS | DS3: FECHA | DT3: TIEMPO RESPUESTA | DU3: OBS | DV3: REVISION | DW3: TRANSMITTAL SEH | DX3: TIEMPO RESPUESTA | DY3: FECHA | DZ3: TRANSMITTAL SIEMENS | EA3: FECHA | EB3: TIEMPO RESPUESTA | EC3: OBS | ED3: REVISION | EE3: TRANSMITTAL SEH | EF3: TIEMPO RESPUESTA | EG3: FECHA | EH3: TRANSMITTAL SIEMENS | EI3: FECHA | EJ3: TIEMPO RESPUESTA | EK3: OBS | EL3: REVISION | EM3: TRANSMITTAL SEH | EN3: TIEMPO RESPUESTA | EO3: FECHA | EP3: TRANSMITTAL SIEMENS | EQ3: FECHA | ER3: TIEMPO RESPUESTA | ES3: OBS | ET3: REVISION | EU3: TRANSMITTAL SEH | EV3: TIEMPO RESPUESTA | EW3: FECHA | EX3: TRANSMITTAL SIEMENS | EY3: FECHA | EZ3: TIEMPO RESPUESTA | FA3: OBS | FB3: REVISION | FC3: TRANSMITTAL SEH | FD3: TIEMPO RESPUESTA | FE3: FECHA | FF3: TRANSMITTAL SIEMENS | FG3: FECHA | FH3: TIEMPO RESPUESTA | FI3: OBS | FJ3: REVISION | FK3: TRANSMITTAL SEH | FL3: TIEMPO RESPUESTA | FM3: FECHA | FN3: TRANSMITTAL SIEMENS | FO3: FECHA | FP3: TIEMPO RESPUESTA | FQ3: OBS | FR3: REVISION | FS3: TRANSMITTAL SEH | FT3: TIEMPO RESPUESTA | FU3: FECHA | FV3: TRANSMITTAL SIEMENS | FW3: FECHA | FX3: TIEMPO RESPUESTA | FY3: OBS | FZ3: REVISION | GA3: TRANSMITTAL SEH | GB3: TIEMPO RESPUESTA | GC3: FECHA | GD3: TRANSMITTAL SIEMENS | GE3: FECHA | GF3: TIEMPO RESPUESTA | GG3: OBS | GH3: REVISION | GI3: TRANSMITTAL SEH | GJ3: TIEMPO RESPUESTA | GK3: FECHA | GL3: TRANSMITTAL SIEMENS | GM3: FECHA | GN3: TIEMPO RESPUESTA | GO3: OBS | GP3: REVISION | GQ3: TRANSMITTAL SEH | GR3: TIEMPO RESPUESTA | GS3: FECHA | GT3: TRANSMITTAL SIEMENS | GU3: FECHA | GV3: TIEMPO RESPUESTA | GW3: OBS | GX3: REVISION | GY3: TRANSMITTAL SEH | GZ3: TIEMPO RESPUESTA | HA3: FECHA | HB3: TRANSMITTAL SIEMENS | HC3: FECHA | HD3: TIEMPO RESPUESTA | HE3: OBS | HF3: REVISION | HG3: TRANSMITTAL SEH | HH3: TIEMPO RESPUESTA | HI3: FECHA | HJ3: TRANSMITTAL SIEMENS | HK3: FECHA | HL3: TIEMPO RESPUESTA | HM3: OBS | HN3: REVISION | HO3: TRANSMITTAL SEH | HP3: TIEMPO RESPUESTA | HQ3: FECHA | HR3: TRANSMITTAL SIEMENS | HS3: FECHA | HT3: TIEMPO RESPUESTA | HU3: OBS
B4: 1 | D4: ALL | E4: 6021-RES-CP-011 | F4: N/A | G4: N/A | H4: RESUMEN SEMANAL SEH - Nº11 | M4: CP | N4: 0 | O4: 136 | P4: 46036 | R4: Entregado | V4: 0 | W4: 136 | Y4: 46036
B5: 2 | D5: ALL | E5: 6021-LOG-0001 | F5: N/A | G5: N/A | H5: TALABRE - LOG DE CAMBIOS AL 14-01-2026 | M5: CP | N5: 0 | O5: 136 | P5: 46036 | R5: Entregado | S5: =IF(R5="Aprobado con comentarios / Emitir en Rev_0", NETWORKDAYS(Q5,TODAY(),Hoja1!$C$3:$C$25),0) -> 0 | T5: =IF(R5="Revisión INN",NETWORKDAYS(P5,TODAY(),Hoja1!$C$3:$C$25),0) -> 0 | U5: =ROUNDUP(((COUNTA(V5:GW5)/4)/2),0) -> 1 | V5: 0 | W5: 136 | Y5: 46036
B6: 3 | D6: ALL | E6: OT-6021-IAS-CP-0021 | F6: N/A | G6: N/A | H6: INFORME DE AVANCE SEMANAL Nº21 AL 14-01-2027 | M6: CP | N6: 0 | O6: 136 | P6: 46036 | R6: Entregado | S6: =IF(R6="Aprobado con comentarios / Emitir en Rev_0", NETWORKDAYS(Q6,TODAY(),Hoja1!$C$3:$C$25),0) -> 0 | T6: =IF(R6="Revisión INN",NETWORKDAYS(P6,TODAY(),Hoja1!$C$3:$C$25),0) -> 0 | U6: =ROUNDUP(((COUNTA(V6:GW6)/4)/2),0) -> 1 | V6: 0 | W6: 136 | Y6: 46036
E7: OT-6021-IAS-CP-0034 | F7: N/A | H7: 'INFORME DE AVANCE SEMANAL Nº34 AL 14-04-2026 | M7: CP | N7: 0 | O7: 262 | P7: 46126 | R7: ENTREGADO | S7: =IF(R7="Aprobado con comentarios / Emitir en Rev_0", NETWORKDAYS(Q7,TODAY(),Hoja1!$C$3:$C$25),0) -> 0 | T7: =IF(R7="Revisión INN",NETWORKDAYS(P7,TODAY(),Hoja1!$C$3:$C$25),0) -> 0 | U7: =ROUNDUP(((COUNTA(V7:GW7)/4)/2),0) -> 0
E8: 6021-RES-CP-024 | F8: N/A | H8: RESUMEN SEMANAL SEH - Nº24 | M8: CP | N8: 0 | O8: 262 | P8: 46126 | R8: ENTREGADO | S8: =IF(R8="Aprobado con comentarios / Emitir en Rev_0", NETWORKDAYS(Q8,TODAY(),Hoja1!$C$3:$C$25),0) -> 0 | T8: =IF(R8="Revisión INN",NETWORKDAYS(P8,TODAY(),Hoja1!$C$3:$C$25),0) -> 0 | U8: =ROUNDUP(((COUNTA(V8:GW8)/4)/2),0) -> 0
B9: 4 | C9: N/A | D9: 3713-SEL-1001 | E9: SEH-OT-6021-PR-CP-001 | F9: N/A | G9: N/A | H9: PLANIFICACIÓN - CARTA GANTT // SALA TAG 3713-SEL-1001 | I9: - | K9: - | M9: CP | N9: 0 | O9: 262 | P9: 46126 | Q9: 45937 | R9: ENTREGADO | S9: =IF(R9="Aprobado con comentarios / Emitir en Rev_0", NETWORKDAYS(Q9,TODAY(),Hoja1!$C$3:$C$25),0) -> 0 | T9: =IF(R9="Revisión INN",NETWORKDAYS(P9,TODAY(),Hoja1!$C$3:$C$25),0) -> 0 | U9: =ROUNDUP(((COUNTA(V9:GW9)/4)/2),0) -> 13 | V9: B | W9: 5 | X9: - | Y9: 45895 | Z9: 12 | AA9: 45904 | AB9: =AA9-Y9 -> 9 | AC9: Comentado / Emitir Rev.C | AD9: C | AE9: 17 | AF9: =AG9-AA9 -> 7 | AG9: 45911 | AH9: 25 | AI9: 45926 | AJ9: =AG9-AI9 -> -15 | AK9: Aprobado con comentarios menores / pasar a 0 | AL9: 0 | AM9: 30 | AN9: =AO9-AI9 -> 4 | AO9: 45930 | AP9: 32 | AQ9: 45937 | AR9: =AQ9-AO9 -> 7 | AS9: Aprobado | AT9: 0 | AU9: 35 | AV9: =AW9-AQ9 -> 0 | AW9: 45937 | AX9: - | AY9: - | AZ9: - | BA9: - | BB9: 0 | BC9: 57 | BE9: 45958 | BF9: - | BG9: - | BH9: - | BI9: - | BJ9: 0 | BK9: 64 | BL9: - | BM9: 45966 | BR9: 0 | BS9: 70 | BU9: 45972 | BV9: - | BW9: - | BX9: - | BY9: - | BZ9: 0 | CA9: 83 | CC9: 45986 | CH9: 0 | CI9: 92 | CJ9: - | CK9: 45993 | CP9: 0 | CQ9: 102 | CS9: 46000 | CX9: 0 | CY9: 86 | DA9: 46008 | DF9: 0 | DG9: 117 | DI9: 46014 | DN9: 0 | DO9: 126 | DQ9: 46022 | DV9: 0 | DW9: 128 | DY9: 46028 | ED9: 0 | EE9: 136 | EG9: 46036 | EL9: 0 | EM9: 142 | EO9: 46042 | ET9: 0 | EU9: 154 | EW9: 46049 | FB9: 0 | FC9: 164 | FE9: 46057 | FJ9: 0 | FK9: 166 | FM9: 46064 | FR9: 0 | FS9: 194 | FU9: 46077 | FZ9: 0 | GA9: 225 | GC9: 46099 | GH9: 0 | GI9: 255 | GK9: 46119 | GP9: 0 | GQ9: 262 | GS9: 46126
B10: 5 | C10: N/A | D10: 3762-SEL-1101 | E10: SEH-OT-6021-PR-CP-002 | F10: N/A | G10: N/A | H10: PLANIFICACIÓN - CARTA GANTT // SALA TAG 3762-SEL-1101 | I10: - | K10: - | M10: CP | N10: 0 | O10: 262 | P10: 46126 | Q10: 45937 | R10: ENTREGADO | S10: =IF(R10="Aprobado con comentarios / Emitir en Rev_0", NETWORKDAYS(Q10,TODAY(),Hoja1!$C$3:$C$25),0) -> 0 | T10: =IF(R10="Revisión INN",NETWORKDAYS(P10,TODAY(),Hoja1!$C$3:$C$25),0) -> 0 | U10: =ROUNDUP(((COUNTA(V10:GW10)/4)/2),0) -> 13 | V10: B | W10: 5 | X10: - | Y10: 45895 | Z10: 12 | AA10: 45904 | AB10: =AA10-Y10 -> 9 | AC10: Comentado / Emitir Rev.C | AD10: C | AE10: 17 | AF10: =AG10-AA10 -> 7 | AG10: 45911 | AH10: 25 | AI10: 45926 | AJ10: =AG10-AI10 -> -15 | AK10: Aprobado con comentarios menores / pasar a 0 | AL10: 0 | AM10: 30 | AN10: =AO10-AI10 -> 4 | AO10: 45930 | AP10: 32 | AQ10: 45937 | AR10: =AQ10-AO10 -> 7 | AS10: Aprobado | AT10: 0 | AU10: 35 | AV10: =AW10-AQ10 -> 0 | AW10: 45937 | AX10: - | AY10: - | AZ10: - | BA10: - | BB10: 0 | BC10: 57 | BE10: 45958 | BF10: - | BG10: - | BH10: - | BI10: - | BJ10: 0 | BK10: 64 | BL10: - | BM10: 45966 | BR10: 0 | BS10: 70 | BU10: 45972 | BV10: - | BW10: - | BX10: - | BY10: - | BZ10: 0 | CA10: 83 | CC10: 45986 | CH10: 0 | CI10: 92 | CJ10: - | CK10: 45993 | CP10: 0 | CQ10: 102 | CS10: 46000 | CX10: 0 | CY10: 86 | DA10: 46008 | DF10: 0 | DG10: 117 | DI10: 46014 | DN10: 0 | DO10: 126 | DQ10: 46022 | DV10: 0 | DW10: 128 | DY10: 46028 | ED10: 0 | EE10: 136 | EG10: 46036 | EL10: 0 | EM10: 142 | EO10: 46042 | ET10: 0 | EU10: 154 | EW10: 46049 | FB10: 0 | FC10: 164 | FE10: 46057 | FJ10: 0 | FK10: 166 | FM10: 46064 | FR10: 0 | FS10: 194 | FU10: 46077 | FZ10: 0 | GA10: 225 | GC10: 46099 | GH10: 0 | GI10: 255 | GK10: 46119 | GP10: 0 | GQ10: 262 | GS10: 46126
B11: 8 | C11: N/A | D11: ALL | E11: OT-6021-IAS-CP-0001 | F11: N/A | G11: N/A | H11: INFORME DE AVANCE SEMANAL Nº1 | I11: N/A | K11: N/A | M11: CP | N11: 0 | O11: 8 | P11: 45898 | Q11: - | R11: Entregado | S11: =IF(R11="Aprobado con comentarios / Emitir en Rev_0", NETWORKDAYS(Q11,TODAY(),Hoja1!$C$3:$C$25),0) -> 0 | T11: =IF(R11="Revisión INN",NETWORKDAYS(P11,TODAY(),Hoja1!$C$3:$C$25),0) -> 0 | U11: =ROUNDUP(((COUNTA(V11:GW11)/4)/2),0) -> 1 | V11: 0 | W11: 8 | Y11: 45898
B12: 9 | C12: N/A | D12: ALL | E12: OT-6021-IAS-CP-0002 | F12: N/A | G12: N/A | H12: INFORME DE AVANCE SEMANAL Nº2 | I12: N/A | K12: N/A | M12: CP | N12: 0 | O12: 12 | P12: 45904 | Q12: - | R12: Entregado | S12: =IF(R12="Aprobado con comentarios / Emitir en Rev_0", NETWORKDAYS(Q12,TODAY(),Hoja1!$C$3:$C$25),0) -> 0 | T12: =IF(R12="Revisión INN",NETWORKDAYS(P12,TODAY(),Hoja1!$C$3:$C$25),0) -> 0 | U12: =ROUNDUP(((COUNTA(V12:GW12)/4)/2),0) -> 1 | V12: 0 | W12: 12 | Y12: 45905
B13: 10 | C13: N/A | D13: ALL | E13: OT-6021-IAS-CP-0003 | F13: N/A | G13: N/A | H13: INFORME DE AVANCE SEMANAL Nº3 | I13: N/A | K13: N/A | M13: CP | N13: 0 | O13: 14 | P13: 45909 | Q13: - | R13: Entregado | S13: =IF(R13="Aprobado con comentarios / Emitir en Rev_0", NETWORKDAYS(Q13,TODAY(),Hoja1!$C$3:$C$25),0) -> 0 | T13: =IF(R13="Revisión INN",NETWORKDAYS(P13,TODAY(),Hoja1!$C$3:$C$25),0) -> 0 | U13: =ROUNDUP(((COUNTA(V13:GW13)/4)/2),0) -> 1 | V13: 0 | W13: 14 | Y13: 45909
B14: 11 | C14: N/A | D14: ALL | E14: OT-6021-IAS-CP-0004 | F14: N/A | G14: N/A | H14: INFORME DE AVANCE SEMANAL Nº4 | I14: N/A | K14: N/A | M14: CP | N14: 0 | P14: 45916 | Q14: - | R14: Entregado | S14: =IF(R14="Aprobado con comentarios / Emitir en Rev_0", NETWORKDAYS(Q14,TODAY(),Hoja1!$C$3:$C$25),0) -> 0 | T14: =IF(R14="Revisión INN",NETWORKDAYS(P14,TODAY(),Hoja1!$C$3:$C$25),0) -> 0 | U14: =ROUNDUP(((COUNTA(V14:GW14)/4)/2),0) -> 1 | V14: 0 | W14: 20 | Y14: 45916
B15: 12 | C15: N/A | D15: ALL | E15: OT-6021-IAS-CP-0005 | F15: N/A | G15: N/A | H15: INFORME DE AVANCE SEMANAL Nº5 | I15: N/A | K15: N/A | M15: CP | N15: 0 | O15: 23 | P15: 45923 | Q15: - | R15: Entregado | S15: =IF(R15="Aprobado con comentarios / Emitir en Rev_0", NETWORKDAYS(Q15,TODAY(),Hoja1!$C$3:$C$25),0) -> 0 | T15: =IF(R15="Revisión INN",NETWORKDAYS(P15,TODAY(),Hoja1!$C$3:$C$25),0) -> 0 | U15: =ROUNDUP(((COUNTA(V15:GW15)/4)/2),0) -> 1 | V15: 0 | W15: 23 | Y15: 45923
B16: 13 | C16: N/A | D16: ALL | E16: OT-6021-IAS-CP-0007 | F16: N/A | G16: N/A | H16: INFORME DE AVANCE SEMANAL Nº7 | I16: N/A | K16: N/A | M16: CP | N16: 0 | O16: 35 | P16: 45937 | Q16: - | R16: Entregado | S16: =IF(R16="Aprobado con comentarios / Emitir en Rev_0", NETWORKDAYS(Q16,TODAY(),Hoja1!$C$3:$C$25),0) -> 0 | T16: =IF(R16="Revisión INN",NETWORKDAYS(P16,TODAY(),Hoja1!$C$3:$C$25),0) -> 0 | U16: =ROUNDUP(((COUNTA(V16:GW16)/4)/2),0) -> 1 | V16: 0 | W16: 35 | Y16: 45937
B17: 14 | C17: N/A | D17: ALL | E17: 6021-LTA-CP-0001 | F17: N/A | G17: N/A | H17: LISTADO DE ENTREGABLES | I17: Cerrado | K17: Cerrado | M17: CP-INF | N17: 0 | O17: 64 | P17: 45943 | Q17: 45979 | R17: Aprobado | S17: =IF(R17="Aprobado con comentarios / Emitir en Rev_0", NETWORKDAYS(Q17,TODAY(),Hoja1!$C$3:$C$25),0) -> 0 | T17: =IF(R17="Revisión INN",NETWORKDAYS(P17,TODAY(),Hoja1!$C$3:$C$25),0) -> 0 | U17: =ROUNDUP(((COUNTA(V17:GW17)/4)/2),0) -> 3 | V17: B | W17: 2 | Y17: 45887 | Z17: 9 | AA17: 45898 | AB17: =AA17-Y17 -> 11 | AC17: Aprobado con comentarios / Emitir Rev.C | AD17: C | AE17: 10 | AF17: =AG17-AA17 -> 5 | AG17: 45903 | AH17: 28 | AI17: 45931 | AJ17: =AI17-AG17 -> 28 | AK17: Aprobado con comentarios / Emitir en Rev_0 | AL17: 0 | AM17: 40 | AN17: =AO17-AI17 -> 12 | AO17: 45943 | AP17: 64 | AQ17: 45981 | AS17: Aprobado
B18: 15 | C18: N/A | D18: ALL | E18: 6021-MTR-CP-0001 | F18: N/A | G18: N/A | H18: MATRIZ DE COMUNICACIÓN SEGURA | I18: N/A | K18: N/A | M18: CP-INF | N18: 0 | O18: 1 | P18: 45887 | R18: Entregado | S18: =IF(R18="Aprobado con comentarios / Emitir en Rev_0", NETWORKDAYS(Q18,TODAY(),Hoja1!$C$3:$C$25),0) -> 0 | T18: =IF(R18="Revisión INN",NETWORKDAYS(P18,TODAY(),Hoja1!$C$3:$C$25),0) -> 0 | U18: =ROUNDUP(((COUNTA(V18:GW18)/4)/2),0) -> 1 | V18: 0 | W18: 1 | Y18: 45887
B19: 16 | C19: N/A | D19: ALL | E19: OT-6021-IAS-CP-0008 | F19: N/A | G19: N/A | H19: INFORME DE AVANCE SEMANAL Nº8 | M19: CP | N19: 0 | O19: 44 | P19: 45944 | Q19: - | R19: Entregado | S19: =IF(R19="Aprobado con comentarios / Emitir en Rev_0", NETWORKDAYS(Q19,TODAY(),Hoja1!$C$3:$C$25),0) -> 0 | T19: =IF(R19="Revisión INN",NETWORKDAYS(P19,TODAY(),Hoja1!$C$3:$C$25),0) -> 0 | U19: =ROUNDUP(((COUNTA(V19:GW19)/4)/2),0) -> 1 | V19: 0 | W19: 44 | Y19: 45944
B20: 17 | C20: N/A | D20: ALL | E20: OT-6021-IAS-CP-0009 | F20: N/A | G20: N/A | H20: INFORME DE AVANCE SEMANAL Nº9 | M20: CP | N20: 0 | O20: 50 | P20: 45951 | R20: Entregado | S20: =IF(R20="Aprobado con comentarios / Emitir en Rev_0", NETWORKDAYS(Q20,TODAY(),Hoja1!$C$3:$C$25),0) -> 0 | T20: =IF(R20="Revisión INN",NETWORKDAYS(P20,TODAY(),Hoja1!$C$3:$C$25),0) -> 0 | U20: =ROUNDUP(((COUNTA(V20:GW20)/4)/2),0) -> 1 | V20: 0 | W20: 50 | Y20: 45951
B21: 18 | D21: ALL | E21: 6021-RES-CP-003 | F21: N/A | G21: N/A | H21: RESUMEN SEMANAL SEH - Nº3 | M21: CP | N21: 0 | O21: 80 | P21: 45981 | R21: Entregado | S21: =IF(R21="Aprobado con comentarios / Emitir en Rev_0", NETWORKDAYS(Q21,TODAY(),Hoja1!$C$3:$C$25),0) -> 0 | T21: =IF(R21="Revisión INN",NETWORKDAYS(P21,TODAY(),Hoja1!$C$3:$C$25),0) -> 0 | U21: =ROUNDUP(((COUNTA(V21:GW21)/4)/2),0) -> 1 | V21: 0 | W21: 80 | Y21: 45981
B22: 19 | C22: N/A | D22: ALL | E22: OT-6021-IAS-CP-0010 | F22: N/A | G22: N/A | H22: INFORME DE AVANCE SEMANAL Nº10 | I22: N/A | M22: CP | N22: 0 | O22: 57 | P22: 45958 | Q22: - | R22: Entregado | S22: =IF(R22="Aprobado con comentarios / Emitir en Rev_0", NETWORKDAYS(Q22,TODAY(),Hoja1!$C$3:$C$25),0) -> 0 | T22: =IF(R22="Revisión INN",NETWORKDAYS(P22,TODAY(),Hoja1!$C$3:$C$25),0) -> 0 | U22: =ROUNDUP(((COUNTA(V22:GW22)/4)/2),0) -> 1 | V22: 0 | W22: 57 | Y22: 45958
B23: 20 | C23: N/A | D23: ALL | E23: 6021-MIN-ING-0001_Nº1_26.08.25 | F23: N/A | G23: N/A | H23: MINUTA DE REUNIÓN INGENIERIA Nº1 | M23: MINU | N23: 0 | O23: 6 | P23: 45895 | R23: Entregado | S23: =IF(R23="Aprobado con comentarios / Emitir en Rev_0", NETWORKDAYS(Q23,TODAY(),Hoja1!$C$3:$C$25),0) -> 0 | T23: =IF(R23="Revisión INN",NETWORKDAYS(P23,TODAY(),Hoja1!$C$3:$C$25),0) -> 0 | U23: =ROUNDUP(((COUNTA(V23:GW23)/4)/2),0) -> 1 | V23: 0 | W23: 6 | Y23: 45895 | AK23: Aprobado con comentarios menores / pasar a 0
B24: 21 | C24: N/A | D24: ALL | E24: 6021-MIN-ING-0001_Nº2_02.09.25 | F24: N/A | G24: N/A | H24: MINUTA DE REUNIÓN INGENIERIA Nº2 | M24: MINU | N24: 0 | O24: 9 | P24: 45903 | R24: Entregado | S24: =IF(R24="Aprobado con comentarios / Emitir Rev_B", NETWORKDAYS(Q24,TODAY(),Hoja1!$C$3:$C$25),0) -> 0 | T24: =IF(R24="Revisión INN",NETWORKDAYS(P24,TODAY(),Hoja1!$C$3:$C$25),0) -> 0 | U24: =ROUNDUP(((COUNTA(V24:GW24)/4)/2),0) -> 1 | V24: 0 | W24: 9 | Y24: 45903
B25: 22 | C25: N/A | D25: ALL | E25: 6021-MIN-ING-0001_Nº3_09.09.25 | F25: N/A | G25: N/A | H25: MINUTA DE REUNIÓN INGENIERIA Nº3 | M25: MINU | N25: 0 | O25: 21 | P25: 45922 | R25: Entregado | S25: =IF(R25="Aprobado con comentarios / Emitir Rev_B", NETWORKDAYS(Q25,TODAY(),Hoja1!$C$3:$C$25),0) -> 0 | T25: =IF(R25="Revisión INN",NETWORKDAYS(P25,TODAY(),Hoja1!$C$3:$C$25),0) -> 0 | U25: =ROUNDUP(((COUNTA(V25:GW25)/4)/2),0) -> 1 | V25: 0 | W25: 21 | Y25: 45922
B26: 23 | C26: N/A | D26: ALL | E26: 6021-MIN-ING-0001_Nº4_16.09.25 | F26: N/A | G26: N/A | H26: MINUTA DE REUNIÓN INGENIERIA Nº4 | I26: N/A | K26: N/A | L26: N/A | M26: MINU | N26: 0 | O26: 21 | P26: 45922 | R26: Entregado | S26: =IF(R26="Aprobado con comentarios / Emitir Rev_B", NETWORKDAYS(Q26,TODAY(),Hoja1!$C$3:$C$25),0) -> 0 | T26: =IF(R26="Revisión INN",NETWORKDAYS(P26,TODAY(),Hoja1!$C$3:$C$25),0) -> 0 | U26: =ROUNDUP(((COUNTA(V26:GW26)/4)/2),0) -> 1 | V26: 0 | W26: 21 | Y26: 45922
B27: 24 | C27: N/A | D27: ALL | E27: 6021-MIN-ING-0001_Nº5_23.09.25 | F27: N/A | G27: N/A | H27: MINUTA DE REUNIÓN INGENIERIA Nº5 | I27: N/A | K27: N/A | L27: N/A | M27: MINU | N27: 0 | O27: 24 | P27: 45924 | R27: Entregado | S27: =IF(R27="Aprobado con comentarios / Emitir Rev_B", NETWORKDAYS(Q27,TODAY(),Hoja1!$C$3:$C$25),0) -> 0 | T27: =IF(R27="Revisión INN",NETWORKDAYS(P27,TODAY(),Hoja1!$C$3:$C$25),0) -> 0 | U27: =ROUNDUP(((COUNTA(V27:GW27)/4)/2),0) -> 1 | V27: 0 | W27: 23 | Y27: 45923
B28: 25 | C28: N/A | D28: ALL | E28: 6021-MIN-ING-0001_Nº6_30.09.25 | F28: N/A | G28: N/A | H28: MINUTA DE REUNIÓN INGENIERIA Nº6 | I28: N/A | K28: N/A | L28: N/A | M28: MINU | N28: 0 | O28: 29 | P28: 45930 | R28: Entregado | S28: =IF(R28="Aprobado con comentarios / Emitir Rev_B", NETWORKDAYS(Q28,TODAY(),Hoja1!$C$3:$C$25),0) -> 0 | T28: =IF(R28="Revisión INN",NETWORKDAYS(P28,TODAY(),Hoja1!$C$3:$C$25),0) -> 0 | U28: =ROUNDUP(((COUNTA(V28:GW28)/4)/2),0) -> 1 | V28: 0 | W28: 29 | Y28: 45930
B29: 26 | C29: N/A | D29: ALL | E29: 6021-MIN-ING-0001_Nº7_07.10.25 | F29: N/A | G29: N/A | H29: MINUTA DE REUNIÓN INGENIERIA Nº7 | I29: N/A | K29: N/A | L29: N/A | M29: MINU | N29: 0 | O29: 36 | P29: 45938 | R29: Entregado | S29: =IF(R29="Aprobado con comentarios / Emitir Rev_B", NETWORKDAYS(Q29,TODAY(),Hoja1!$C$3:$C$25),0) -> 0 | T29: =IF(R29="Revisión INN",NETWORKDAYS(P29,TODAY(),Hoja1!$C$3:$C$25),0) -> 0 | U29: =ROUNDUP(((COUNTA(V29:GW29)/4)/2),0) -> 1 | V29: 0 | W29: 36 | Y29: 45938
B30: 27 | C30: N/A | D30: ALL | E30: 6021-MDC-HD-0001 | F30: N/A | G30: N/A | H30: CRITERIOS DE DISEÑO MCE (UNIFICACIÓN DE DATOS) | I30: N/A | K30: N/A | M30: ME | N30: 0 | O30: 16 | P30: 45890 | Q30: 45912 | R30: Respondido | S30: =IF(R30="Aprobado con comentarios / Emitir en Rev_0", NETWORKDAYS(Q30,TODAY(),Hoja1!$C$3:$C$25),0) -> 0 | T30: =IF(R30="Revisión INN",NETWORKDAYS(P30,TODAY(),Hoja1!$C$3:$C$25),0) -> 0 | U30: =ROUNDUP(((COUNTA(V30:GW30)/4)/2),0) -> 1 | V30: 0 | W30: 3 | Y30: 45890 | Z30: 16 | AA30: 45912 | AB30: =AA30-Y30 -> 22 | AC30: Respondido
B31: 111 | C31: N/A | D31: 3713-SEL-1001 | E31: 6021-CER-QA-0101 | F31: 66OP12044-INN-PRET-ME-CE0220 | G31: N23CC02-PEL01-3713-CERES-00001 | H31: CERTIFICADOS DE ACERO NCH203 SALA ELÉCTRICA 3713-SEL-1001 | M31: QA | N31: 0 | O31: 124 | P31: 46029 | Q31: 46050 | R31: Aprobado / Emitir Rev_1 | S31: =IF(R31="Aprobado / Emitir Rev_1", NETWORKDAYS(Q31,TODAY(),Hoja1!$C$3:$C$25),0) -> 57 | T31: =IF(R31="Revisión INN",NETWORKDAYS(P31,TODAY(),Hoja1!$C$3:$C$25),0) -> 0 | U31: =ROUNDUP(((COUNTA(V31:GW31)/4)/2),0) -> 4 | V31: A | W31: 52 | Y31: 45953 | Z31: 66 | AA31: 45987 | AC31: Aprobado / Emitir en Rev_0 | AD31: 0 | AE31: 94 | AG31: 45994 | AH31: 94 | AI31: 45995 | AK31: Rechazado / Emitir en Rev_B | AL31: B | AM31: 96 | AN31: - | AO31: 45995 | AP31: 89 | AQ31: 46014 | AS31: Aprobado / Emitir Rev_0 | AT31: 0 | AU31: 130 | AW31: 46029 | AX31: 124 | AY31: 46050 | BA31: Aprobado / Emitir Rev_1
B32: 29 | C32: N/A | D32: ALL | E32: 6021-M-FB-0001 | F32: N/A | G32: N/A | H32: PLANO CÁNCAMO DE IZAJE | I32: Cerrado | K32: Cerrado | M32: ME-INF | N32: 1 | O32: 79 | P32: 45929 | Q32: 46007 | R32: Aprobado | S32: =IF(R32="Aprobado con comentarios / Emitir en Rev_0", NETWORKDAYS(Q32,TODAY(),Hoja1!$C$3:$C$25),0) -> 0 | T32: =IF(R32="Revisión INN",NETWORKDAYS(P32,TODAY(),Hoja1!$C$3:$C$25),0) -> 0 | U32: =ROUNDUP(((COUNTA(V32:GW32)/4)/2),0) -> 2 | V32: 0 | W32: 11 | Y32: 45904 | Z32: 14 | AA32: 45911 | AB32: =AA32-Y32 -> 7 | AC32: Aprobado | AD32: 1 | AE32: 27 | AF32: =AG32-AA32 -> 18 | AG32: 45929 | AH32: 79 | AI32: 46007 | AK32: Aprobado
B33: 118 | C33: N/A | D33: 3762-SEL-1101 | E33: 6021-CER-QA-0201 | F33: 66OP12044-INN-PRET-ME-CE1420 | G33: N23CC02-PEL01-3762-CERES-00001 | H33: CERTIFICADOS DE ACERO NCH203 SALA ELÉCTRICA 3762-SEL-1101 | M33: QA | N33: 0 | O33: 124 | P33: 46029 | Q33: 46050 | R33: Aprobado / Emitir Rev_1 | S33: =IF(R33="Aprobado / Emitir Rev_1", NETWORKDAYS(Q33,TODAY(),Hoja1!$C$3:$C$25),0) -> 57 | T33: =IF(R33="Revisión INN",NETWORKDAYS(P33,TODAY(),Hoja1!$C$3:$C$25),0) -> 0 | U33: =ROUNDUP(((COUNTA(V33:GW33)/4)/2),0) -> 4 | V33: A | W33: 52 | Y33: 45953 | Z33: 66 | AA33: 45987 | AC33: Aprobado / Emitir en Rev_0 | AD33: 0 | AE33: 94 | AG33: 45994 | AH33: 94 | AI33: 45995 | AK33: Rechazado / Emitir en Rev_B | AL33: B | AM33: 96 | AN33: - | AO33: 45995 | AP33: 89 | AQ33: 46014 | AS33: Aprobado / Emitir Rev_0 | AT33: 0 | AU33: 130 | AW33: 46029 | AX33: 124 | AY33: 46050 | BA33: Aprobado / Emitir Rev_1
B34: 119 | C34: N/A | D34: 3762-SEL-1201 | E34: 6021-CER-QA-0301 | F34: 66OP12044-INN-PRET-ME-CE1620 | G34: N23CC02-PEL01-3762-CERES-00002 | H34: CERTIFICADOS DE ACERO NCH203 SALA ELÉCTRICA 3762-SEL-1201 | M34: QA | N34: 0 | O34: 124 | P34: 46029 | Q34: 46050 | R34: Aprobado / Emitir Rev_1 | S34: =IF(R34="Aprobado / Emitir Rev_1", NETWORKDAYS(Q34,TODAY(),Hoja1!$C$3:$C$25),0) -> 57 | T34: =IF(R34="Revisión INN",NETWORKDAYS(P34,TODAY(),Hoja1!$C$3:$C$25),0) -> 0 | U34: =ROUNDUP(((COUNTA(V34:GW34)/4)/2),0) -> 4 | V34: A | W34: 52 | Y34: 45953 | Z34: 66 | AA34: 45987 | AC34: Aprobado / Emitir en Rev_0 | AD34: 0 | AE34: 94 | AG34: 45994 | AH34: CORREO ALEJANDRA_RECHAZADO_NCH | AI34: 45995 | AK34: Rechazado / Emitir en Rev_B | AL34: B | AM34: 96 | AN34: - | AO34: 45995 | AP34: 89 | AQ34: 46014 | AS34: Aprobado / Emitir Rev_0 | AT34: 0 | AU34: 130 | AW34: 46029 | AX34: 124 | AY34: 46050 | BA34: Aprobado / Emitir Rev_1
B35: 59 | C35: SECUNDARIO | D35: ALL | E35: 6021-PRO-QA-0006 | F35: 66OP12044-INN-PRET-GE-PR0008 | G35: N23CC02-PEL01-0000-PROMD-00003 | H35: PROCEDIMIENTOS DE ENSAYOS NO DESTRUCTIVOS | L35: SEH Debe emitir REV_1 atendiendo comentarios de TTAL 88 en carpeta Respuestas de INN a cliente_REV.A a la 0 | M35: QA | N35: 1 | O35: 152 | P35: 46049 | Q35: 46014 | R35: Revisión INN | S35: =IF(R35="Aprobado con comentarios / Emitir Rev_1", NETWORKDAYS(Q35,TODAY(),Hoja1!$C$3:$C$25),0) -> 0 | T35: =IF(R35="Revisión INN",NETWORKDAYS(P35,TODAY(),Hoja1!$C$3:$C$25),0) -> 58 | U35: =ROUNDUP(((COUNTA(V35:GW35)/4)/2),0) -> 3 | V35: B | W35: 39 | Y35: 45943 | Z35: - | AA35: - | AB35: - | AC35: - | AD35: B | AE35: 54 | AG35: 45954 | AH35: 57 | AI35: 45965 | AK35: Aprobado sin comentarios / Emitir Rev_0 | AL35: 0 | AM35: 76 | AO35: 45979 | AP35: 66 / 88 | AQ35: 27-11-2025 / 23-12-2025 | AS35: Aprobado con comentarios / Emitir Rev_1 | AT35: 1 | AU35: 152 | AW35: 46049
B36: 39 | C36: PRINCIPAL PLATAFORMAS | D36: 5335-SEL-0001 | E36: 6021-PLA-ME-0501 | F36: 66OP12044-INN-PRET-ME-PL0878 | G36: N/A | H36: PLANO DE DISPOSICIÓN Y DETALLES DE PLATAFORMAS, BARANDAS Y ESCALERAS SALA ELÉCTRICA 5335-SEL-0001 (LAYOUT DISPOSICIÓN PLATAFORMAS) | I36: =Q36+5 -> 46102 | J36: 2 | K36: - | M36: ME | N36: B | O36: 152 | P36: 46086 | Q36: 46097 | R36: Aprobado / Emitir Rev_0 | S36: =IF(R36="Aprobado / Emitir Rev_0", NETWORKDAYS(Q36,TODAY(),Hoja1!$C$3:$C$25),0) -> 24 | T36: =IF(R36="Revisión INN",NETWORKDAYS(P36,TODAY(),Hoja1!$C$3:$C$25),0) -> 0 | U36: =ROUNDUP(((COUNTA(V36:GW36)/4)/2),0) -> 2 | V36: A | W36: 72 | Y36: 45974 | Z36: 67 | AA36: 45988 | AC36: Aprobado con comentarios / Emitir Rev_B | AD36: B | AE36: 212 | AG36: 46086 | AH36: 152 | AI36: 46097 | AK36: Aprobado / Emitir Rev_0
B37: 34 | C37: PRINCIPAL PLATAFORMAS | D37: 3713-SEL-1001 | E37: 6021-MDC-ME-0102 | F37: 66OP12044-INN-PRET-ME-MC0217 | G37: N23CC02-PEL01-3713-MDCES-00002 | H37: MEMORIA DE CÁLCULO SÍSMICO ESTRUCTURAL PLATAFORMAS SALA ELÉCTRICA 3713-SEL-1001 | K37: =P37+5 -> 46069 | M37: ME | N37: 0 | O37: 153 | P37: 46064 | Q37: 45988 | R37: Aprobado | S37: =IF(R37="Aprobado con comentarios / Emitir Rev_0", NETWORKDAYS(Q37,TODAY(),Hoja1!$C$3:$C$25),0) -> 0 | T37: =IF(R37="Revisión INN",NETWORKDAYS(P37,TODAY(),Hoja1!$C$3:$C$25),0) -> 0 | U37: =ROUNDUP(((COUNTA(V37:GW37)/4)/2),0) -> 3 | V37: A | W37: 47 | Y37: 45950 | Z37: 51 | AA37: 45959 | AB37: =AA37-Y37 -> 9 | AC37: Aprobado con comentarios / Emitir en Rev_B | AD37: B | AE37: 61 | AF37: =AG37-AA37 -> 0 | AG37: 45959 | AH37: 67 | AI37: 45988 | AK37: Aprobado con comentarios / Emitir Rev_0 | AL37: 0 | AM37: 170 | AO37: 46064 | AP37: 153 | AQ37: 46097 | AS37: Aprobado
B38: 35 | C38: PRINCIPAL PLATAFORMAS | D38: 3713-SEL-1001 | E38: 6021-PLA-ME-0107 | F38: 66OP12044-INN-PRET-ME-PL0295 | G38: N/A | H38: PLANO DE DISPOSICIÓN Y DETALLES DE PLATAFORMAS, BARANDAS Y ESCALERAS SALA ELÉCTRICA 3713-SEL-1001 (LAYOUT DISPOSICIÓN PLATAFORMAS) | I38: =Q38+5 -> 46123 | J38: 2 | K38: - | M38: ME | N38: 0 | O38: 175 | P38: 46100 | Q38: 46118 | R38: Aprobado | S38: =IF(R38="Aprobado / emitir Rev_0", NETWORKDAYS(Q38,TODAY(),Hoja1!$C$3:$C$25),0) -> 0 | T38: =IF(R38="Revisión INN",NETWORKDAYS(P38,TODAY(),Hoja1!$C$3:$C$25),0) -> 0 | U38: =ROUNDUP(((COUNTA(V38:GW38)/4)/2),0) -> 3 | V38: A | W38: 72 | Y38: 45974 | Z38: 67 | AA38: 45988 | AB38: =AA38-Y38 -> 14 | AC38: Aprobado con comentarios / Emitir Rev_B | AD38: B | AE38: 190 | AG38: 46076 | AH38: 146 | AI38: 46091 | AK38: Aprobado / emitir Rev_0 | AL38: 0 | AM38: 231 | AO38: 46100 | AP38: 175 | AQ38: 46118 | AS38: Aprobado
B39: 46 | C39: N/A | D39: ALL | E39: 6021-MNL-ME-0002 | F39: 66OP12044-INN-PRET-ME-MA0017 | G39: N23CC02-PEL01-0000-MNLME-00001 | H39: MANUAL DE INSTALACIÓN SALAS ELÉCTRICAS | I39: =Q39+5 -> 46046 | J39: 3 | K39: - | M39: ME | N39: B | O39: 173 | P39: 46065 | Q39: 46041 | R39: Revisión INN | S39: =IF(R39="Aprobado con comentarios / Emitir Rev_B", NETWORKDAYS(Q39,TODAY(),Hoja1!$C$3:$C$25),0) -> 0 | T39: =IF(R39="Revisión INN",NETWORKDAYS(P39,TODAY(),Hoja1!$C$3:$C$25),0) -> 46 | U39: =ROUNDUP(((COUNTA(V39:GW39)/4)/2),0) -> 2 | V39: A | W39: 107 | Y39: 46006 | Z39: 111 | AA39: 46041 | AC39: Aprobado con comentarios / Emitir Rev_B | AD39: B | AE39: 174 | AG39: 46065
B40: 38 | C40: N/A | D40: ALL | E40: 6021-PRO-ME-0001 | F40: 66OP12044-INN-PRET-GE-PR0187 | G40: N/A | H40: PROCEDIMIENTO DE TRANSPORTE TERRESTRE SALA ELÉCTRICA | I40: =Q40+5 -> 46130 | J40: 3 | K40: - | M40: ME | N40: 0 | O40: 185 | P40: 46065 | Q40: 46125 | R40: Aprobado | S40: =IF(R40="Aprobado / Emitir Rev_0", NETWORKDAYS(Q40,TODAY(),Hoja1!$C$3:$C$25),0) -> 0 | T40: =IF(R40="Revisión INN",NETWORKDAYS(P40,TODAY(),Hoja1!$C$3:$C$25),0) -> 0 | U40: =ROUNDUP(((COUNTA(V40:GW40)/4)/2),0) -> 2 | V40: B | W40: 103 | Y40: 46002 | Z40: 111 | AA40: 46041 | AC40: Aprobado / Emitir Rev_0 | AD40: 0 | AE40: 173 | AG40: 46065 | AH40: 185 | AI40: 46125 | AK40: Aprobado
...

Sheet INGENIERÍA FABRICA
K5: EMITIR ASBUI+'[OT-6011_Master documental 16.08.23.xlsx]INGENIERÍA FABRICA'!T REV.2 CON COMENTARIOS LEVANTADOS
J8: CONTROL DOCUMENTAL
J9: MASTER INGENIERÍA
J10: CÓDIGO
J11: B
J12: =TODAY() -> 46130
D13: CANTIDAD DE DOCUMENTOS | G13: RESUMEN ACTUALIZADO DE ENTREGA | L13: 1ERA EMISIÓN | P13: 2DA EMISIÓN | T13: 3ERA EMISIÓN | X13: 4TA EMISIÓN | AB13: 5TA EMISIÓN | AF13: 6TA EMISIÓN | AJ13: 7ma EMISIÓN | AN13: 8va EMISIÓN | AR13: 9na EMISIÓN | AV13: 10ma EMISIÓN | AZ13: 11ma EMISIÓN | BD13: 12ma EMISIÓN | BH13: 13ra EMISIÓN
A14: ITEM | B14: PÁGINAS | C14: COPIAS CONTROLADAS | D14: CÓDIGO | E14: DESCRIPCIÓN DOCUMENTO | F14: ESPECIALIDAD | G14: REVISIÓN | H14: ACTAS DE ENTREGA | I14: FECHA DE ENTREGA A FABRICA | J14: ESTADO | K14: MOVIMIENTOS DEL DOCUMENTO | L14: REVISION | M14: ACTAS DE ENTREGA | N14: FECHA | O14: Entregado | P14: REVISION | Q14: ACTAS DE ENTREGA | R14: FECHA | S14: Entrega | T14: REVISION | U14: ACTAS DE ENTREGA | V14: FECHA | W14: Entregado | X14: REVISION | Y14: ACTAS DE ENTREGA | Z14: FECHA | AA14: Entregado | AB14: REVISION | AC14: ACTAS DE ENTREGA | AD14: FECHA | AE14: Entregado | AF14: REVISION | AG14: ACTAS DE ENTREGA | AH14: FECHA | AI14: Entregado | AJ14: REVISION | AK14: ACTAS DE ENTREGA | AL14: FECHA | AM14: Entregado | AN14: REVISION | AO14: ACTAS DE ENTREGA | AP14: FECHA | AQ14: Entregado | AR14: REVISION | AS14: ACTAS DE ENTREGA | AT14: FECHA | AU14: Entregado | AV14: REVISION | AW14: ACTAS DE ENTREGA | AX14: FECHA | AY14: Entregado | AZ14: REVISION | BA14: ACTAS DE ENTREGA | BB14: FECHA | BC14: Entregado | BD14: REVISION | BE14: ACTAS DE ENTREGA | BF14: FECHA | BG14: Entregado | BH14: REVISION | BI14: ACTAS DE ENTREGA | BJ14: FECHA | BK14: Entregado
A15: 1 | B15: 2 | C15: 2 PRODUCCIÓN / 1 PLEGADO / 1 EXPEDITOR / 1 CALIDAD | D15: 6021-M-FB-0002 | E15: PLANO PAD GROUND 3713-SEL-1001 | F15: ME | G15: 2 | H15: 92 | I15: 46114 | J15: ENTREGADO | K15: =ROUNDUP(((COUNTA(L15:AI15)/4)/2),0) -> 1 | L15: 1 | M15: 1 | N15: 45923 | O15: ENTREGADO | P15: 2 | Q15: 92 | R15: 46114 | S15: ENTREGADO
A16: 2 | B16: 2 | C16: 2 PRODUCCIÓN / 1 PLEGADO / 1 EXPEDITOR / 1 CALIDAD | D16: 6021-M-FB-0042 | E16: PLANO PAD GROUND 3762-SEL-1101 | F16: ME | G16: 0 | H16: 92 | I16: 46114 | J16: ENTREGADO | K16: =ROUNDUP(((COUNTA(L16:AI16)/4)/2),0) -> 1 | L16: 0 | M16: 92 | N16: 46114 | O16: ENTREGADO
A17: 3 | B17: 2 | C17: 2 PRODUCCIÓN / 1 PLEGADO / 1 EXPEDITOR / 1 CALIDAD | D17: 6021-M-FB-0043 | E17: PLANO PAD GROUND 3762-SEL-1201 | F17: ME | G17: 0 | H17: 92 | I17: 46114 | J17: ENTREGADO | K17: =ROUNDUP(((COUNTA(L17:AI17)/4)/2),0) -> 1 | L17: 0 | M17: 92 | N17: 46114 | O17: ENTREGADO
A18: 4 | B18: 1 | C18: 4 PRODUCCIÓN | D18: 6021-M-FB-0001 | E18: PLANO CANCAMO DE IZAJE | F18: ME | G18: 2 | H18: 48 | I18: 46069 | J18: ENTREGADO | K18: =ROUNDUP(((COUNTA(L18:AI18)/4)/2),0) -> 1 | L18: 1 | M18: 12 | N18: 45995 | O18: ENTREGADO | P18: 2 | Q18: 48 | R18: 46069 | S18: ENTREGADO
A19: 5 | B19: 5 | C19: 3 PRODUCCIÓN / 1 EXPEDITOR | D19: N23CC02-PEL01-0000-300ME-00002 | E19: PLANO DE UNIÓN DE MÓDULOS SALA ELÉCTRICA 3713-SEL 1001 / 3762-SEL-1101 / 3762-SEL-1201 | F19: ME | G19: 3 | H19: 49 | I19: 46070 | J19: ENTREGADO | K19: =ROUNDUP(((COUNTA(L19:AI19)/4)/2),0) -> 3 | L19: B | M19: 2 | N19: 45938 | O19: ENTREGADO | P19: 0 | Q19: 7 | R19: 45964 | S19: ENTREGADO | T19: 1 | U19: 15 | V19: 46007 | W19: ENTREGADO | X19: 2 | Y19: 26 | Z19: 46034 | AA19: Entregado | AB19: 3 | AC19: 49 | AD19: 46070 | AE19: ENTREGADO
A20: 6 | B20: 21 | C20: 2 PRODUCCIÓN / 1 EXPEDITOR / 1 CALIDAD | D20: N23CC02-PEL01-3713-300ME-00001 | E20: PLANO DETALLE ESTRUCTURAL BASE SALA ELÉCTRICA 3713-SEL-1001 | F20: ME | G20: 2 | H20: 94 | I20: 46125 | J20: ENTREGADO | K20: =ROUNDUP(((COUNTA(L20:AI20)/4)/2),0) -> 3 | L20: B | M20: 2 | N20: 45938 | O20: ENTREGADO | P20: B | Q20: 6 | R20: 45958 | S20: ENTREGADO | T20: 0 | U20: 7 | V20: 45964 | W20: ENTREGADO | X20: 0_RL1 | Y20: 8 | Z20: 45971 | AA20: ENTREGADO | AB20: 0_RL2 | AC20: 10 | AD20: 45993 | AE20: ENTREGADO | AF20: 0_RL3 | AG20: 13 | AH20: 46002 | AI20: ENTREGADO | AJ20: 0_RL4 | AK20: 18 | AL20: 46010 | AM20: ENTREGADO | AN20: 1 | AO20: 61 | AP20: 46086 | AQ20: ENTREGADO | AR20: 2 | AS20: 94 | AT20: 46125
A21: 63 | B21: 7 | C21: 2 PRODUCCIÓN / 1 EXPEDITOR / 1 CALIDAD | D21: 66OP12044-INN-PRET-ME-PL0288 | E21: DISPOSICIÓN Y DETALLES CALADOS DE PISO 3713-SEL-1001 | F21: ME | G21: 2_RL1 | H21: 90 | I21: 46113 | J21: ENTREGADO | K21: =ROUNDUP(((COUNTA(L21:AI21)/4)/2),0) -> 1 | L21: 2 | M21: 61 | N21: 46086 | O21: ENTREGADO | P21: 2_RL1 | Q21: 90 | R21: 46113 | S21: ENTREGADO
A22: 8 | B22: 9 | C22: 2 PRODUCCIÓN / 1 EXPEDITOR / 1 CALIDAD | D22: N23CC02-PEL01-3713-300ME-00002 | E22: PLANO DE DETALLE ESTRUCTURAL PILARES SALA ELÉCTRICA 3713-SEL-1001 | F22: ME | G22: 2 | H22: 85 | I22: 46107 | J22: ENTREGADO | K22: =ROUNDUP(((COUNTA(L22:AI22)/4)/2),0) -> 3 | L22: 0 | M22: 7 | N22: 45964 | O22: ENTREGADO | P22: 0_RL1 | Q22: 11 | R22: 45992 | S22: ENTREGADO | T22: 1 | U22: 20 | V22: 46022 | W22: Entregado | X22: 1_RL2 | Y22: 72 | Z22: 46098 | AA22: ENTREGADO | AB22: 2 | AC22: 85 | AD22: 46107 | AE22: ENTREGADO
A23: 9 | B23: 5 | C23: 3 PRODUCCIÓN | D23: 6021-M-FB-1001 | E23: PLANO BOTA AGUA PORTON Y PUERTA | F23: ME | G23: 0 | H23: 14 | I23: 46006 | J23: ENTREGADO | K23: =ROUNDUP(((COUNTA(L23:AI23)/4)/2),0) -> 1 | L23: 0 | M23: 14 | N23: 46006 | O23: ENTREGADO
A24: 10 | B24: 15 | C24: 2 PRODUCCIÓN / 1 PLEGADO 1 EXPEDITOR / 1 CALIDAD | D24: 66OP12044-INN-PRET-ME-PL0466 | E24: PLANO DE DISPOSICIÓN Y DETALLES DE PLATAFORMAS, BARANDAS Y ESCALERAS SALA ELÉCTRICA 3717-SEL-1001 | F24: ME | G24: 2 | H24: 81 | I24: º | J24: ENTREGADO | K24: =ROUNDUP(((COUNTA(L24:AI24)/4)/2),0) -> 2 | L24: 0 | M24: 42 | N24: 46056 | O24: ENTREGADO | P24: 1 | Q24: 50 | R24: 46071 | S24: Entregado | T24: 1_RL2 | U24: 68 | V24: 46094 | W24: Entregado | X24: 2 | Y24: 81 | Z24: 46106
A25: 11 | B25: 11 | C25: 2 PRODUCCIÓN / 1 EXPEDITOR / 1 CALIDAD | D25: N23CC02-PEL01-3762-300ME-00002 | E25: PLANO DE DETALLE ESTRUCTURAL PILARES SALA ELÉCTRICA 3762-SEL-1101 | F25: ME | G25: 2 | H25: 85 | I25: 46107 | J25: ENTREGADO | K25: =ROUNDUP(((COUNTA(L25:AI25)/4)/2),0) -> 2 | L25: 0 | M25: 7 | N25: 45964 | O25: ENTREGADO | P25: 0_RL1 | Q25: 11 | R25: 45992 | S25: ENTREGADO | T25: 1 | U25: 20 | V25: 46022 | W25: Entregado | X25: 2 | Y25: 85 | Z25: 46107 | AA25: ENTREGADO
A26: 12 | B26: 5 | C26: 3 PRODUCCIÓN | D26: 6021-M-FB-1002 | E26: PLANO BOTA AGUA EQUIPOS | F26: ME | G26: 0 | H26: 14 | I26: 46006 | J26: ENTREGADO | K26: =ROUNDUP(((COUNTA(L26:AI26)/4)/2),0) -> 1 | L26: 0 | M26: 14 | N26: 46006 | O26: ENTREGADO
A27: 13 | B27: 11 | C27: 2 PRODUCCIÓN / 1 EXPEDITOR / 1 CALIDAD | D27: N23CC02-PEL01-3762-300ME-00005 | E27: PLANO DE DETALLE ESTRUCTURAL PILARES SALA ELÉTRICA 3762-SEL-1201 | F27: ME | G27: 2 | H27: 85 | I27: 46107 | J27: ENTREGADO | K27: =ROUNDUP(((COUNTA(L27:AI27)/4)/2),0) -> 2 | L27: 0 | M27: 7 | N27: 45964 | O27: ENTREGADO | P27: 0_RL1 | Q27: 11 | R27: 45992 | S27: ENTREGADO | T27: 1 | U27: 20 | V27: 46022 | W27: Entregado | X27: 2 | Y27: 85 | Z27: 46107 | AA27: ENTREGADO
A28: 14 | B28: 9 | C28: 2 PRODUCCIÓN / 1 PLEGADO / 1 EXPEDITOR / 1 CALIDAD | D28: N23CC02-PEL01-3713-300ME-00003 | E28: PLANO DE DETALLE ESTRUCTURAL TECHOS SALA ELÉCTRICA 3713-SEL-1001 | F28: ME | G28: 1_RL5 | H28: 93 | I28: 46119 | J28: ENTREGADO | K28: =ROUNDUP(((COUNTA(L28:AI28)/4)/2),0) -> 3 | L28: 0 | M28: 7 | N28: 45964 | O28: ENTREGADO | P28: 0_RL1 | Q28: 14 | R28: 46006 | S28: ENTREGADO | T28: 1 | U28: 21 - Producción / 22 Calidad | V28: 46028 | W28: ENTREGADO | X28: 1_RL1 | Y28: 38 | Z28: 46049 | AA28: ENTREGADO | AB28: 1_RL3 | AC28: 71 | AD28: 46098 | AE28: ENTREGADO | AF28: 1_RL4 | AG28: 84 | AH28: 46107 | AI28: ENTREGADO | AJ28: 1_RL5 | AK28: 93 | AL28: 46119 | AM28: ENTREGADO
A29: 15 | B29: 1 | C29: 3 PRODUCCIÓN | D29: 6021-M-FB-1000 | E29: PLANO ATIESADOR | F29: ME | G29: 1 | H29: 16 | I29: 46008 | J29: ENTREGADO | K29: =ROUNDUP(((COUNTA(L29:AI29)/4)/2),0) -> 1 | L29: 0 | M29: 3 | N29: 45943 | O29: ENTREGADO | P29: 1 | Q29: 16 | R29: 46008 | S29: ENTREGADO
A30: 16 | B30: 3 | C30: 4 PRODUCCIÓN | D30: 6021-M-FB-0003 | E30: PLANO PANEL TÍPICO MURO INT. Y EXT. | F30: ME | G30: 2 | H30: 43 | I30: 46056 | J30: ENTREGADO | K30: =ROUNDUP(((COUNTA(L30:AI30)/4)/2),0) -> 2 | L30: 0 | M30: 4 | N30: 45946 | O30: ENTREGADO | P30: 1 | Q30: 25 | R30: 46031 | S30: ENTREGADO | T30: 2 | U30: 43 | V30: 46056 | W30: ENTREGADO
A31: 17 | B31: 1 | C31: 3 PRODUCCIÓN | D31: 6021-M-FB-0004 | E31: PLANO PANEL TÍPICO TECHO | F31: ME | G31: 1 | H31: 5 | I31: 45946 | J31: ENTREGADO | K31: =ROUNDUP(((COUNTA(L31:AI31)/4)/2),0) -> 1 | L31: 0 | M31: 4 | N31: 45946 | O31: ENTREGADO | P31: 1 | Q31: 5 | R31: 45958 | S31: ENTREGADO
A32: 18 | B32: 2 | C32: 4 PRODUCCIÓN / 1 EXPEDITOR | D32: 6021-M-FB-0005 | E32: PLANO PANEL TÍPICO CIELO | F32: ME | G32: 2 | H32: 44 | I32: 46056 | J32: ENTREGADO | K32: =ROUNDUP(((COUNTA(L32:AI32)/4)/2),0) -> 2 | L32: 0 | M32: 4 | N32: 45946 | O32: ENTREGADO | P32: 1 | Q32: 5 | R32: 45958 | S32: ENTREGADO | T32: 2 | U32: 44 | V32: 46056 | W32: ENTREGADO
A33: 19 | B33: 2 | C33: 2 PRODUCCIÓN | D33: 6021-M-FB-0101 | E33: DEFORMACIÓN ADMISIBLE BASE ESTRUCTURAL 3713-SEL-1001 | F33: ME | G33: 0 | H33: 9 | I33: 45972 | J33: ENTREGADO | K33: =ROUNDUP(((COUNTA(L33:AI33)/4)/2),0) -> 1 | L33: 0 | M33: 9 | N33: 45972 | O33: ENTREGADO
A34: 20 | B34: 2 | C34: 2 PRODUCCIÓN | D34: 6021-M-FB-0201 | E34: DEFORMACIÓN ADMISIBLE BASE ESTRUCTURAL 3762-SEL-1101 | F34: ME | G34: 0 | H34: 9 | I34: 45972 | J34: ENTREGADO | K34: =ROUNDUP(((COUNTA(L34:AI34)/4)/2),0) -> 1 | L34: 0 | M34: 9 | N34: 45973 | O34: ENTREGADO
A35: 21 | B35: 2 | C35: 2 PRODUCCIÓN | D35: 6021-M-FB-0301 | E35: DEFORMACIÓN ADMISIBLE BASE ESTRUCTURAL 3762-SEL-1202 | F35: ME | G35: 0 | H35: 9 | I35: 45973 | J35: ENTREGADO | K35: =ROUNDUP(((COUNTA(L35:AI35)/4)/2),0) -> 1 | L35: 0 | M35: 9 | N35: 45974 | O35: ENTREGADO
A36: 22 | B36: 11 | C36: 2 PRODUCCIÓN / 1 EXPEDITOR / 1 CALIDAD | D36: N23CC02-PEL01-3762-300ME-00003 | E36: PLANO DE DETALLE ESTRUCTURAL TECHOS SALA ELÉCTRICA 3762-SEL-1101 | F36: ME | G36: 1_RL4 | H36: 87 | I36: 46107 | J36: ENTREGADO | K36: =ROUNDUP(((COUNTA(L36:AI36)/4)/2),0) -> 3 | L36: 0 | M36: 7 | N36: 45964 | O36: ENTREGADO | P36: 0_RL1 | Q36: 14 | R36: 46006 | S36: ENTREGADO | T36: 1 | U36: 21 - Producción / 22 Calidad | V36: 46028 | W36: ENTREGADO | X36: 1_RL1 | Y36: 38 | Z36: 46049 | AA36: ENTREGADO | AB36: 1_RL3 | AC36: 71 | AD36: 46098 | AE36: ENTREGADO | AF36: 1_RL4 | AG36: 87 | AH36: 46107
A37: 23 | B37: 11 | C37: 2 PRODUCCIÓN / 1 EXPEDITOR / 1 CALIDAD | D37: N23CC02-PEL01-3762-300ME-00006 | E37: PLANO DE DETALLE ESTRUCTURAL TECHOS SALA ELÉCTRICA 3762-SEL-1201 | F37: ME | G37: 1_RL4 | H37: 87 | I37: 46107 | J37: ENTREGADO | K37: =ROUNDUP(((COUNTA(L37:AI37)/4)/2),0) -> 3 | L37: 0 | M37: 7 | N37: 45964 | O37: ENTREGADO | P37: 0_RL1 | Q37: 14 | R37: 46006 | S37: ENTREGADO | T37: 1 | U37: 21 - Producción / 22 Calidad | V37: 46028 | W37: ENTREGADO | X37: 1_RL1 | Y37: 38 | Z37: 46049 | AA37: ENTREGADO | AB37: 1_RL3 | AC37: 71 | AD37: 46098 | AE37: ENTREGADO | AF37: 1_RL4 | AG37: 87 | AH37: 46107
A38: 24 | B38: 1 | C38: 5 PRODUCCIÓN / 1 CALIDAD | D38: 6021-M-FB-0010 | E38: PLANO PLACAS REFUERZO | F38: ME | G38: 1 | H38: 18 | I38: 46010 | J38: ENTREGADO | K38: =ROUNDUP(((COUNTA(L38:AI38)/4)/2),0) -> 1 | L38: 0 | M38: 16 | N38: 46008 | O38: ENTREGADO | P38: 1 | Q38: 18 | R38: 46010 | S38: ENTREGADO
A39: 25 | B39: 2 | C39: 4 PRODUCCIÓN | D39: 6021-M-FB-0009 | E39: DETALLE DE MONTAJE PLANCHA DE PISO | F39: ME | G39: 3 | H39: 36 | I39: 46042 | J39: ENTREGADO | K39: =ROUNDUP(((COUNTA(L39:AI39)/4)/2),0) -> 2 | L39: 0 | M39: 17 | N39: 46008 | O39: ENTREGADO | P39: 1 | Q39: 24 | R39: 46029 | S39: ENTREGADO | T39: 2 | U39: 25 | V39: 46031 | W39: ENTREGADO | X39: 3 | Y39: 36 | Z39: 46042 | AA39: ENTREGADO
A40: 26 | B40: 2 | C40: 4 PRODUCCIÓN / 1 CALIDAD | D40: 6021-M-FB-0012 | E40: PLANO DETALLE SOLDADURA | F40: ME | G40: 0 | H40: 19 | I40: 46014 | J40: ENTREGADO | K40: =ROUNDUP(((COUNTA(L40:AI40)/4)/2),0) -> 1 | L40: 0 | M40: 19 | N40: 46014 | O40: ENTREGADO
A41: 27 | B41: 6 | C41: 3 PRODUCCIÓN | D41: 6021-M-FB-0102 | E41: DISPOSICIÓN PLANCHA DE PISO 3713-SEL-1001 | F41: ME | G41: 0 | H41: 23 | I41: 46029 | J41: ENTREGADO | K41: =ROUNDUP(((COUNTA(L41:AI41)/4)/2),0) -> 1 | L41: 0 | M41: 23 | N41: 46029 | O41: ENTREGADO
A42: 28 | B42: 8 | C42: 4 PRODUCCIÓN | D42: 6021-M-FB-0302 | E42: DISPOSICIÓN PLANCHA DE PISO 3762-1201 | F42: ME | G42: 0 | H42: 24 | I42: 46029 | J42: ENTREGADO | K42: =ROUNDUP(((COUNTA(L42:AI42)/4)/2),0) -> 1 | L42: 0 | M42: 24 | N42: 46029 | O42: ENTREGADO
A43: 29 | B43: 4 | C43: 4 PRODUCCIÓN | D43: N23CC02-PEL01-3713-400ME-00001 | E43: DETALLE DE ANCLAJES Y REACCINES 3713-SEL-1001 | F43: ME | G43: 1 | H43: 25 | I43: 46031 | J43: ENTREGADO | K43: =ROUNDUP(((COUNTA(L43:AI43)/4)/2),0) -> 1 | L43: 1 | M43: 25 | N43: 46031 | O43: ENTREGADO
A44: 30 | B44: 4 | C44: 4 PRODUCCIÓN | D44: N23CC02-PEL01-3762-400ME-00001 | E44: DETALLE DE ANCLAJES Y REACCINES 3762-SEL-1101 | F44: ME | G44: 1 | H44: 25 | I44: 46031 | J44: ENTREGADO | K44: =ROUNDUP(((COUNTA(L44:AI44)/4)/2),0) -> 1 | L44: 1 | M44: 25 | N44: 46031 | O44: ENTREGADO
A45: 31 | B45: 4 | C45: 4 PRODUCCIÓN | D45: N23CC02-PEL01-3762-400ME-00002 | E45: DETALLE DE ANCLAJES Y REACCINES 3762-SEL-1201 | F45: ME | G45: 1 | H45: 25 | I45: 46031 | J45: ENTREGADO | K45: =ROUNDUP(((COUNTA(L45:AI45)/4)/2),0) -> 1 | L45: 1 | M45: 25 | N45: 46031 | O45: ENTREGADO
A46: 32 | B46: 1 | C46: 3 PRODUCCIÓN | D46: 6021-M-FB-0013 | E46: PLANO DETALLE ARRIOSTRAMIENTO PILARES 3713-SEL-1001 | F46: ME | G46: 1 | H46: 37 | I46: 46045 | J46: ENTREGADO | K46: =ROUNDUP(((COUNTA(L46:AI46)/4)/2),0) -> 1 | L46: 0 | M46: 26 | N46: 46036 | O46: ENTREGADO | P46: 1 | Q46: 37 | R46: 46045 | S46: ENTREGADO
...

Sheet Criticidad
A1: SALA / TAG | B1: CÓDIGO SEGURA | C1: CÓDIGO INN | D1: DESCRIPCIÓN DE DOCUMENTO | E1: COMPROMISO DE ENTREGA SEGURA (1 semana corrida) | F1: CRITICIDAD | G1: COMENTARIO INTERNO | H1: ESPECIALIDAD
A2: ALL | B2: 6021-PLA-ME-0006 | C2: 66OP12044-INN-PRET-ME-PL0166 | D2: PLANO DETALLES DE SELLOS MECÁNICOS (SELLOS ROXTEC) | E2: 2 SEMANAS, UNA VEZ RECIBIDA LA INFORMACIÓN DE LOS SELLOS ROXTEC POR PARTE DE INN | F2: 3 | G2: Documento condicionado e envio de información por INN | H2: ME
A3: 3713-SEL-1001 | B3: 6021-LST-ME-0101 | C3: 66OP12044-INN-PRET-GE-LS0281 | D3: LISTADO DE MATERIALES SALA ELÉCTRICA 3713-SEL-1001 | E3: 46002 | F3: * | H3: ME
A4: 3762-SEL-1101 | B4: 6021-LST-ME-0201 | C4: 66OP12044-INN-PRET-GE-LS1498 | D4: LISTADO DE MATERIALES SALA ELÉCTRICA 3762-SEL-1101 | E4: 46002 | F4: * | H4: ME
A5: 3762-SEL-1201 | B5: 6021-LST-ME-0301 | C5: 66OP12044-INN-PRET-GE-LS1698 | D5: LISTADO DE MATERIALES SALA ELÉCTRICA 3762-SEL-1202 | E5: 46002 | F5: * | H5: ME
A6: 3713-SEL-1001 | B6: 6021-PRO-ME-0110 | C6: 66OP12044-INN-PRET-ME-PL0206 | D6: ESQUEMA DE IZAJE Y MANIOBRAS, INCLUYE PESO Y CENTRO DE MASA SALA ELÉCTRICA 3713-SEL-1001 | E6: 45979 | F6: 3 | H6: ME
A7: 3762-SEL-1101 | B7: 6021-PRO-ME-0210 | C7: 66OP12044-INN-PRET-ME-PL1406 | D7: ESQUEMA DE IZAJE Y MANIOBRAS, INCLUYE PESO Y CENTRO DE MASA SALA ELÉCTRICA 3762-SEL-1101 | E7: 45979 | F7: 3 | H7: ME
A8: 3762-SEL-1201 | B8: 6021-PRO-ME-0310 | C8: 66OP12044-INN-PRET-ME-PL1606 | D8: ESQUEMA DE IZAJE Y MANIOBRAS, INCLUYE PESO Y CENTRO DE MASA SALA ELÉCTRICA 3762-SEL-1201 | E8: 45979 | F8: 3 | H8: ME
A9: ALL | B9: 6021-PRO-ME-0001 | C9: 66OP12044-INN-PRET-GE-PR0187 | D9: PROCEDIMIENTO DE TRANSPORTE TERRESTRE SALA ELÉCTRICA | E9: 45989 | F9: 3 | H9: ME
A10: ALL | B10: 6021-MNL-ME-0001 | C10: 66OP12044-INN-PRET-EL-MA0019 | D10: MANUAL DE OPERACIÓN SALAS ELÉCTRICAS | E10: 45989 | F10: 3 | H10: ME
A11: ALL | B11: 6021-MNL-ME-0002 | C11: 66OP12044-INN-PRET-ME-MA0017 | D11: MANUAL DE INSTALACIÓN SALAS ELÉCTRICAS | E11: 45989 | F11: 3 | H11: ME
A12: ALL | B12: 6021-MNL-ME-0003 | C12: 66OP12044-INN-PRET-EL-MA0018 | D12: MANUAL DE MANTENIMIENTO SALAS ELÉCTRICAS | E12: 45989 | F12: 3 | H12: ME
A13: 3713-SEL-1001 | B13: 6021-PLA-ME-0112 | C13: 66OP12044-INN-PRET-ME-PL0293 | D13: PLANO DISPOSICIÓN PARARRAYOS SALA ELÉCTRICA 3713-SEL-1001 | E13: 2 SEMANAS, UNA VEZ RECIBIDO EL ESTUDIO DE APANTALLAMIENTO POR PARTE DE INN | F13: 3 | H13: ME
A14: 3762-SEL-1101 | B14: 6021-PLA-ME-0212 | C14: 66OP12044-INN-PRET-ME-PL1510 | D14: PLANO DISPOSICIÓN PARARRAYOS SALA ELÉCTRICA 3762-SEL-1101 | E14: 2 SEMANAS, UNA VEZ RECIBIDO EL ESTUDIO DE APANTALLAMIENTO POR PARTE DE INN | F14: 3 | H14: ME
A15: 3762-SEL-1201 | B15: 6021-PLA-ME-0312 | C15: 66OP12044-INN-PRET-ME-PL1710 | D15: PLANO DISPOSICIÓN PARARRAYOS SALA ELÉCTRICA 3762-SEL-1202 | E15: 2 SEMANAS, UNA VEZ RECIBIDO EL ESTUDIO DE APANTALLAMIENTO POR PARTE DE INN | F15: 3 | H15: ME
A16: ALL | B16: 6021-PRO-ME-0002 | C16: 66OP12044-INN-PRET-GE-PR0021 | D16: PROCEDIMIENTO DE EMBALAJES, PREPARACIÓN Y MANIPULACIÓN Y ENVÍOS | E16: 45989 | F16: 3 | H16: ME
A17: 3713-SEL-1001 | B17: 6021-CER-ME-0101 | C17: 66OP12044-INN-PRET-ME-CE0291 | D17: CERTIFICADO DE INDIVISIBILIDAD SALA ELÉCTRICA 3713-SEL-1001 | E17: 45989 | F17: 3 | H17: ME
A18: 3762-SEL-1101 | B18: 6021-CER-ME-0201 | C18: 66OP12044-INN-PRET-ME-CE1508 | D18: CERTIFICADO DE INDIVISIBILIDAD SALA ELÉCTRICA 3762-SEL-1101 | E18: 45989 | F18: 3 | H18: ME
A19: 3762-SEL-1201 | B19: 6021-CER-ME-0301 | C19: 66OP12044-INN-PRET-ME-CE1708 | D19: CERTIFICADO DE INDIVISIBILIDAD SALA ELÉCTRICA 3762-SEL-1202 | E19: 45989 | F19: 3 | H19: ME
A20: 5310-SEL-0101 | B20: 6021-MDC-ME-0401 | C20: 66OP12044-INN-PRET-ME-MC0617 | D20: MEMORIA DE CÁLCULO SÍSMICO ESTRUCTURAL PLATAFORMAS SALA ELÉCTRICA 5310-SEL-0101 | E20: A DEFINIR | F20: 2 | H20: ME
A21: 3762-SEL-1101 | B21: 6021-MDC-ME-0202 | C21: 66OP12044-INN-PRET-ME-MC1417 | D21: MEMORIA DE CÁLCULO SÍSMICO ESTRUCTURAL PLATAFORMAS SALA ELÉCTRICA 3762-SEL-1101 | E21: A DEFINIR | F21: 2 | H21: ME
A22: 3762-SEL-1201 | B22: 6021-MDC-ME-0302 | C22: 66OP12044-INN-PRET-ME-MC1617 | D22: MEMORIA DE CÁLCULO SÍSMICO ESTRUCTURAL PLATAFORMAS SALA ELÉCTRICA 3762-SEL-1201 | E22: A DEFINIR | F22: 2 | H22: ME
A23: 3762-SEL-1101 | B23: 6021-PLA-ME-0207 | C23: 66OP12044-INN-PRET-ME-PL1512 | D23: PLANO DE DISPOSICIÓN Y DETALLES DE PLATAFORMAS, BARANDAS Y ESCALERAS SALA ELÉCTRICA 3762-SEL-1101 | E23: 45978 | F23: 2 | H23: ME
A24: 3762-SEL-1201 | B24: 6021-PLA-ME-0307 | C24: 66OP12044-INN-PRET-ME-PL1712 | D24: PLANO DE DISPOSICIÓN Y DETALLES DE PLATAFORMAS, BARANDAS Y ESCALERAS SALA ELÉCTRICA 3762-SEL-1201 | E24: 45978 | F24: 2 | H24: ME
A25: 5310-SEL-0101 | B25: 6021-PLA-ME-0401 | C25: 66OP12044-INN-PRET-ME-PL0676 | D25: PLANO DE DISPOSICIÓN Y DETALLES DE PLATAFORMAS, BARANDAS Y ESCALERAS SALA ELÉCTRICA 5310-SEL-0101 | E25: 45978 | F25: 2 | H25: ME

Sheet SDI o TRL CLIENTE
H3: CONTROL DOCUMENTAL
H4: MASTER INGENIERÍA
H5: CÓDIGO
H6: B
H7: =TODAY() -> 46130
B8: INFORMACIÓN ENTREGADA POR CLIENTE (EXCEPTO TRANSMITTALS CON ESTATUS DE ENTREGABLES ) | F8: DETALLE | CC8: COMENTARIOS CLIENTE | CG8: EMISIÓN | CK8: COMENTARIOS CLIENTE | CO8: EMISIÓN | CS8: COMENTARIOS CLIENTE | CW8: EMISIÓN | DA8: COMENTARIOS CLIENTE | DE8: EMISIÓN | DI8: COMENTARIOS CLIENTE | DM8: EMISIÓN | DQ8: COMENTARIOS CLIENTE | DU8: EMISIÓN | DY8: COMENTARIOS CLIENTE
B9: ITEM | C9: CÓDIGO SDI,TRL o CORREO DE RESPALDO INNOMOTICS | D9: DESCRIPCIÓN DOCUMENTO | E9: ESPECIALIDAD | F9: CANTIDAD DE ARCHIVOS | G9: FECHA DE RECEPCIÓN | H9: ESTATUS | CA9: TIEMPO RESPUESTA | CB9: FECHA | CC9: TRANSMITTAL SIEMENS | CD9: FECHA | CE9: TIEMPO RESPUESTA | CF9: OBS | CG9: REVISION | CH9: TRANSMITTAL SEH | CI9: TIEMPO RESPUESTA | CJ9: FECHA | CK9: TRANSMITTAL SIEMENS | CL9: FECHA | CM9: TIEMPO RESPUESTA | CN9: OBS | CO9: REVISION | CP9: TRANSMITTAL SEH | CQ9: TIEMPO RESPUESTA | CR9: FECHA | CS9: TRANSMITTAL SIEMENS | CT9: FECHA | CU9: TIEMPO RESPUESTA | CV9: OBS | CW9: REVISION | CX9: TRANSMITTAL SEH | CY9: TIEMPO RESPUESTA | CZ9: FECHA | DA9: TRANSMITTAL SIEMENS | DB9: FECHA | DC9: TIEMPO RESPUESTA | DD9: OBS | DE9: REVISION | DF9: TRANSMITTAL SEH | DG9: TIEMPO RESPUESTA | DH9: FECHA | DI9: TRANSMITTAL SIEMENS | DJ9: FECHA | DK9: TIEMPO RESPUESTA | DL9: OBS | DM9: REVISION | DN9: TRANSMITTAL SEH | DO9: TIEMPO RESPUESTA | DP9: FECHA | DQ9: TRANSMITTAL SIEMENS | DR9: FECHA | DS9: TIEMPO RESPUESTA | DT9: OBS | DU9: REVISION | DV9: TRANSMITTAL SEH | DW9: TIEMPO RESPUESTA | DX9: FECHA | DY9: TRANSMITTAL SIEMENS | DZ9: FECHA | EA9: TIEMPO RESPUESTA | EB9: OBS
B10: 1 | C10: 66OP12044-INN-SEH-T0001 | D10: INFORMACIÓN DE INICIO // ITP METALMECÁNICO Y PROGRAMA DE INSPECCIONES 3 // KOM INN-SEGURA // MATRIZ COMUNICACIONES INN | E10: ME-QA | F10: 5 PDF / 1 EXCEL / 1 ZIP | G10: 45881 | H10: INFORMATIVO
B11: 2 | C11: 66OP12044-INN-SEH-T0002 | D11: ESPECIFICACIONES TÉCNICAS DE SALAS // ESTÁNDARES DE DISEÑO BARANDAS // LAYOUT // LISTADO DE EQUIPOS // ENTREGABLES METALMECÁNICOS TALABRE | E11: ME | F11: 1 ZIP CON 4 CARPETAS + PDF de Entregables Metalmecánicos solicitados por cliente (Descarga por Wetransfer, ya que secufex arrojaba error de carga) | G11: 45887 | H11: INFORMATIVO
B12: 3 | C12: 66OP12044-INN-SEH-T0003 | D12: RESPUESTA A SDI MECÁNICA SEGURA Nº1_660P12044-INN-SEH-SDI001 | E12: ME | F12: 1 PDF | G12: 45888 | H12: INFORMATIVO
B13: 4 | C13: 66OP12044-INN-SEH-T0004 | D13: FORMATOS PLANOS CAD Y PORTADA DOCUMENTOS | E13: ME | F13: 2 (1 WORD Y 1 CAD) | G13: 45890 | H13: INFORMATIVO
B14: 5 | C14: 66OP12044-INN-SEH-T0008 | D14: INFORMACIÓN DE EQUIPOS PLANOS CCM / PLANOS CDC / PLANOS GIS-SWG / LISTADO DE EQUIPOS / DIMENSIONES UPS / PLANOS VDF / LAYOUT DWG E INFO DE CALADOS | E14: ME - EL | F14: 1 ZIP_SECUFEX PDF , EXCEL Y DWG (29 dctos) | G14: 45895 | H14: INFORMATIVO
B15: 6 | C15: CORREO MARCELO-RENE-JOHAN 29.08.25_VIGA UPN300 VALIDACIÓN | D15: VALIDACIÓN VIGA UPN300 | E15: ME | F15: 1 CORREO | G15: 45898 | H15: INFORMACIÓN PARA COMPRA
B16: 7 | C16: CORREO RAMÓN 02.09.25_RESPUESTAS A CONSULTAS DE T0008 LISTADO DE EQUIPOS | D16: CANTIDAD A CONSIDERAR EN LISTADO DE EQUIPOS (RESPUESTA A CORREO DE JEAN) | E16: ME | F16: 1 CORREO | G16: 45902 | H16: INFORMACIÓN DE EQUIPOS PARA ING
B17: 8 | C17: 66OP12044-INN-SEH-T0011 | D17: HOJA DE DATOS SALA ELÉCTRICA TIPO CONTENEDOR (CÓD. N23CC02-PEL01-0000-HDDEL-00001) | E17: ME | F17: 1 PDF | G17: 45903 | H17: INFOMATIVO
B18: 9 | C18: 66OP12044-INN-SEH-T0013 | D18: DOCUMENTACIÓN SDI Nª3 INN , ADENDA EE.TT , INFO DE SUELOS, CRITERIOS DE DISEÑO , ESQUEMAS DE PINTURA | E18: ME | F18: 6 PDF | G18: 45910 | H18: INFORMATIVO
B19: 10 | C19: 66OP12044-INN-SEH-T0015 | D19: INFORME DE INSPECCIÓN Nº1_09.09.25 | E19: QA | F19: 1 PDF | G19: 45912 | H19: INFOMATIVO
B20: 11 | C20: 66OP12044-INN-SEH-T0016 | D20: SDI 0003 Y PEDESTALES (CRITERIO DE DISEÑO Y COMENTARIOS CODELCO) | E20: ME | F20: 2 PDF | G20: 45912 | H20: INFORMATIVO
B21: 12 | C21: 66OP12044-INN-SEH-T0017 | D21: LAYOUT PLATAFORMAS | E21: ME | F21: 3 PDF | G21: 45916 | H21: INFORMATIVO
... B57: 48 | C57: 66OP12044-INN-SEH-T0053 | D57: PLANOS MECÁNICOS | E57: ME | F57: 9 PDF | G57: 45964 | H57: APROBADO Y APROBADO CON COMENTARIOS
B58: 49 | C58: 66OP12044-INN-SEH-T0054 | D58: PLANOS ESTRUCTURALES BASE | E58: ME | F58: 3 PDF | G58: 45964
B59: 50 | C59: 66OP12044-INN-SEH-T0055 | D59: PLANO UNIÓN DE MODULOS | E59: ME | F59: 1 PDF | G59: 45964 | H59: APROBADO CON COMENTARIOS
B60: 51 | C60: 66OP12044-INN-SEH-T0056 | D60: LOAYOUT INFORMATIVOS + PLANOS VISTAS UNA SALA + IZAMIENTO | E60: ME | F60: 10 PDF | G60: 45965 | H60: INFORMATIVO Y APROBADOS CON COMENTARIOS
B61: 52 | C61: 66OP12044-INN-SEH-T0057 | D61: DOCUMENTOS CALIDAD / COMENTARIOS DE SEH SOBRE DOCUMENTO CREADO POR INN | E61: QA | F61: 4 PDF | G61: 45965 | H61: APROBADOS CON COMENTARIOS
B62: 53 | C62: 66OP12044-INN-SEH-T0058 | D62: DOCUMENTOS MECANICOS APROBADOS CON COMENTARIOS E INFORMATIVOS | E62: ME | F62: 15 PDF | G62: 45966 | H62: APROBADOS CON COMENTARIOS E INFORMATIVOS
B63: 54 | C63: 66OP12044-INN-SEH-T0059 | D63: PLANO PLANTA VISTAS Y SECCIONES / LISTADO DE EQUIPOS 3762-1201 + LOYOUT GENERAL | E63: ME | F63: 3 PDF | G63: 45971 | H63: APROBADOS E INFORMATIVOS
B64: 55 | C64: 66OP12044-INN-SEH-T0060
B65: 56 | C65: 66OP12044-INN-SEH-T0061
B66: 57 | C66: 66OP12044-INN-SEH-T0062
B67: 58 | C67: 66OP12044-INN-SEH-T0063
B68: 59
B69: 60
B70: 61

Sheet MASTER U3
M3: NOMBRE ARCHIVO: | N3: CONTROL DOCUMENTAL
M4: HOJA: | N4: MASTER INGENIERÍA
M5: CÓDIGO: | N5: CÓDIGO
M6: REVISIÓN: | N6: B
M7: FECHA: | N7: =TODAY() -> 46130
B8: INFORMACIÓN ENVIADA Y RECIBIDA POR U3 | D8: CANTIDAD DE DOCUMENTOS | G8: =SUBTOTAL(3,G10:G2019) -> 4 | J8: RESUMEN | R8: 1ERA EMISIÓN | V8: COMENTARIOS CLIENTE | Z8: 2DA EMISIÓN | AD8: COMENTARIOS CLIENTE | AH8: 3ERA EMISIÓN | AL8: COMENTARIOS CLIENTE | AP8: 4TA EMISIÓN | AT8: COMENTARIOS CLIENTE | AX8: 5TA EMISIÓN | BB8: COMENTARIOS CLIENTE | BF8: 6TA EMISIÓN | BJ8: COMENTARIOS CLIENTE | BN8: 7MA EMISIÓN | BR8: COMENTARIOS CLIENTE | BV8: 8VA EMISIÓN | BZ8: COMENTARIOS CLIENTE | CD8: 9NA EMISIÓN | CH8: COMENTARIOS CLIENTE | CL8: 10MA EMISIÓN | CP8: COMENTARIOS CLIENTE | CT8: EMISIÓN | CX8: COMENTARIOS CLIENTE | DB8: EMISIÓN | DF8: COMENTARIOS CLIENTE | DJ8: EMISIÓN | DN8: COMENTARIOS CLIENTE | DR8: EMISIÓN | DV8: COMENTARIOS CLIENTE | DZ8: EMISIÓN | ED8: COMENTARIOS CLIENTE | EH8: EMISIÓN | EL8: COMENTARIOS CLIENTE | EP8: EMISIÓN | ET8: COMENTARIOS CLIENTE | EX8: EMISIÓN | FB8: COMENTARIOS CLIENTE | FF8: EMISIÓN | FJ8: COMENTARIOS CLIENTE | FN8: EMISIÓN | FR8: COMENTARIOS CLIENTE | FV8: EMISIÓN | FZ8: COMENTARIOS CLIENTE | GD8: EMISIÓN | GH8: COMENTARIOS CLIENTE | GL8: EMISIÓN | GP8: COMENTARIOS CLIENTE
B9: ITEM | C9: SALA / TAG | D9: CÓDIGO SEGURA | E9: CÓDIGO INN | F9: CÓDIGO CODELCO CHUQUICAMATA | G9: DESCRIPCIÓN DE DOCUMENTO | H9: COMPROMISO DE ENTREGA | I9: ESPECIALIDAD | J9: REVISIÓN | K9: ACTA DE ENVÍO O TRL | L9: FECHA ÚLTIMO ENVÍO SEH | M9: FECHA RESPUESTA CLIENTE | N9: ESTATUS | O9: INDICADOR SEH | P9: DÍAS EN REVISIÓN INN | Q9: N° EMISIONES REALIZADAS | R9: REVISION | S9: TRANSMITTAL SEH | T9: TIEMPO RESPUESTA | U9: FECHA EMITIDO | V9: TRANSMITTAL | W9: FECHA | X9: TIEMPO RESPUESTA | Y9: OBS | Z9: REVISION | AA9: TRANSMITTAL SEH | AB9: TIEMPO RESPUESTA | AC9: FECHA | AD9: TRANSMITTAL | AE9: FECHA | AF9: TIEMPO RESPUESTA | AG9: OBS | AH9: REVISION | AI9: TRANSMITTAL SEH | AJ9: TIEMPO RESPUESTA | AK9: FECHA | AL9: TRANSMITTAL | AM9: FECHA | AN9: TIEMPO RESPUESTA | AO9: OBS | AP9: REVISION | AQ9: TRANSMITTAL SEH | AR9: TIEMPO RESPUESTA | AS9: FECHA | AT9: TRANSMITTAL | AU9: FECHA | AV9: TIEMPO RESPUESTA | AW9: OBS | AX9: REVISION | AY9: TRANSMITTAL SEH | AZ9: TIEMPO RESPUESTA | BA9: FECHA | BB9: TRANSMITTAL | BC9: FECHA | BD9: TIEMPO RESPUESTA | BE9: OBS | BF9: REVISION | BG9: TRANSMITTAL SEH | BH9: TIEMPO RESPUESTA | BI9: FECHA | BJ9: TRANSMITTAL | BK9: FECHA | BL9: TIEMPO RESPUESTA | BM9: OBS | BN9: REVISION | BO9: TRANSMITTAL SEH | BP9: TIEMPO RESPUESTA | BQ9: FECHA | BR9: TRANSMITTAL | BS9: FECHA | BT9: TIEMPO RESPUESTA | BU9: OBS | BV9: REVISION | BW9: TRANSMITTAL SEH | BX9: TIEMPO RESPUESTA | BY9: FECHA | BZ9: TRANSMITTAL | CA9: FECHA | CB9: TIEMPO RESPUESTA | CC9: OBS | CD9: REVISION | CE9: TRANSMITTAL SEH | CF9: TIEMPO RESPUESTA | CG9: FECHA | CH9: TRANSMITTAL | CI9: FECHA | CJ9: TIEMPO RESPUESTA | CK9: OBS | CL9: REVISION | CM9: TRANSMITTAL SEH | CN9: TIEMPO RESPUESTA | CO9: FECHA | CP9: TRANSMITTAL SIEMENS | CQ9: FECHA | CR9: TIEMPO RESPUESTA | CS9: OBS | CT9: REVISION | CU9: TRANSMITTAL SEH | CV9: TIEMPO RESPUESTA | CW9: FECHA | CX9: TRANSMITTAL SIEMENS | CY9: FECHA | CZ9: TIEMPO RESPUESTA | DA9: OBS | DB9: REVISION | DC9: TRANSMITTAL SEH | DD9: TIEMPO RESPUESTA | DE9: FECHA | DF9: TRANSMITTAL SIEMENS | DG9: FECHA | DH9: TIEMPO RESPUESTA | DI9: OBS | DJ9: REVISION | DK9: TRANSMITTAL SEH | DL9: TIEMPO RESPUESTA | DM9: FECHA | DN9: TRANSMITTAL SIEMENS | DO9: FECHA | DP9: TIEMPO RESPUESTA | DQ9: OBS | DR9: REVISION | DS9: TRANSMITTAL SEH | DT9: TIEMPO RESPUESTA | DU9: FECHA | DV9: TRANSMITTAL SIEMENS | DW9: FECHA | DX9: TIEMPO RESPUESTA | DY9: OBS | DZ9: REVISION | EA9: TRANSMITTAL SEH | EB9: TIEMPO RESPUESTA | EC9: FECHA | ED9: TRANSMITTAL SIEMENS | EE9: FECHA | EF9: TIEMPO RESPUESTA | EG9: OBS | EH9: REVISION | EI9: TRANSMITTAL SEH | EJ9: TIEMPO RESPUESTA | EK9: FECHA | EL9: TRANSMITTAL SIEMENS | EM9: FECHA | EN9: TIEMPO RESPUESTA | EO9: OBS | EP9: REVISION | EQ9: TRANSMITTAL SEH | ER9: TIEMPO RESPUESTA | ES9: FECHA | ET9: TRANSMITTAL SIEMENS | EU9: FECHA | EV9: TIEMPO RESPUESTA | EW9: OBS | EX9: REVISION | EY9: TRANSMITTAL SEH | EZ9: TIEMPO RESPUESTA | FA9: FECHA | FB9: TRANSMITTAL SIEMENS | FC9: FECHA | FD9: TIEMPO RESPUESTA | FE9: OBS | FF9: REVISION | FG9: TRANSMITTAL SEH | FH9: TIEMPO RESPUESTA | FI9: FECHA | FJ9: TRANSMITTAL SIEMENS | FK9: FECHA | FL9: TIEMPO RESPUESTA | FM9: OBS | FN9: REVISION | FO9: TRANSMITTAL SEH | FP9: TIEMPO RESPUESTA | FQ9: FECHA | FR9: TRANSMITTAL SIEMENS | FS9: FECHA | FT9: TIEMPO RESPUESTA | FU9: OBS | FV9: REVISION | FW9: TRANSMITTAL SEH | FX9: TIEMPO RESPUESTA | FY9: FECHA | FZ9: TRANSMITTAL SIEMENS | GA9: FECHA | GB9: TIEMPO RESPUESTA | GC9: OBS | GD9: REVISION | GE9: TRANSMITTAL SEH | GF9: TIEMPO RESPUESTA | GG9: FECHA | GH9: TRANSMITTAL SIEMENS | GI9: FECHA | GJ9: TIEMPO RESPUESTA | GK9: OBS | GL9: REVISION | GM9: TRANSMITTAL SEH | GN9: TIEMPO RESPUESTA | GO9: FECHA | GP9: TRANSMITTAL SIEMENS | GQ9: FECHA | GR9: TIEMPO RESPUESTA | GS9: OBS
B10: 1 | C10: ALL | D10: OT6021-ACTA DE ENVÍO U3_001 | E10: N/A | F10: N/A | G10: CRITERIOS DE DISEÑO E INFORMACIÓN CIVIL PARA GENERAR MDC | H10: WETRANSFER | I10: ME-INF | J10: A-A1-B-0-2 | K10: 1 | L10: 45889 | N10: ENTREGADO A U3 | O10: =IF(N10="Aprobado con comentarios / Emitir Rev.0",TODAY()-M10,0) -> 0 | P10: =IF(N10="Revisión INN",TODAY()-L10,0) -> 0 | Q10: =ROUNDUP(((COUNTA(R10:GS10)/4)/2),0) -> 0
B11: 2 | C11: ALL | D11: 6021-SDI-ME-0001 | E11: 660P12044-INN-SEH-SDI001 | F11: N/A | G11: SOLICITUD DE INFORMACIÓN Nº1 - ING.MECÁNICA // RESPONDIDA POR INN | H11: WETRANSFER | I11: ME-INF | J11: 0 | K11: 1 | L11: 45889 | N11: ENTREGADO A U3 | O11: =IF(N11="Aprobado con comentarios / Emitir Rev.0",TODAY()-M11,0) -> 0 | P11: =IF(N11="Revisión INN",TODAY()-L11,0) -> 0 | Q11: =ROUNDUP(((COUNTA(R11:GS11)/4)/2),0) -> 0
B12: 3 | C12: ALL | D12: 6021-LTA-CP-0001_A | E12: N/A | F12: N/A | G12: LISTADO DE ENTREGABLES U3 | H12: WETRANSFER | I12: ME-INF | J12: A | K12: 1 | L12: 45889 | N12: ENTREGADO A U3 | O12: =IF(N12="Aprobado con comentarios / Emitir Rev.0",TODAY()-M12,0) -> 0 | P12: =IF(N12="Revisión INN",TODAY()-L12,0) -> 0 | Q12: =ROUNDUP(((COUNTA(R12:GS12)/4)/2),0) -> 0
